Workbook

Sheet 26FW 러닝스타일 리스트
A1: 기존품번 | B1: 신규러닝품번 | E1: 품번 | F1: 테마 | I1: 25년 러닝
A2: GF1LJK507 | B2: GF7LJK507 | E2: GF7LJK506 | F2: 가죽 | I2: WBD3L04503 | J2: 러닝
A3: GF1LJK506 | B3: GF7LJK506 | E3: GF8LJP538 | F3: 아르노 | I3: WBD3L04501 | J3: 러닝
A4: WBD3L04503 | B4: GF7LKC503 | E4: GF7LJP536 | F4: 아르노 | I4: WBD3L04505 | J4: 러닝
A5: WBD3L04501 | B5: GF7LKC501 | E5: GF8LCT522 | F5: 아르노 | I5: WBD3L04524 | J5: 러닝
A6: WBE3L04530 | B6: GF7LKC530 | E6: GF7LSH507 | F6: 링클프리 | I6: WBD3L05508 | J6: 러닝
A7: WBD3L04524 | B7: GF7LKC524 | E7: GF3LSH504 | F7: 링클프리 | I7: WBD3L05534 | J7: 러닝
A8: GF1LKC509 | B8: GF7LKC509 | E8: GF7LKC503 | F8: 워셔블 | I8: WBD3L07503 | J8: 러닝
A9: GF1LCT501 | B9: GF7LCT501 | E9: GF7LKC501 | F9: 워셔블 | I9: WBD3L05527 | J9: 러닝
A10: WBE4L10522 | B10: GF8LCT522 | E10: GF7LKC524 | F10: 워셔블 | I10: WBE1L04507 | J10: 러닝
A11: GF1LKP502 | B11: GF7LKP502 | E11: GF8LKC550 | F11: 노르딕,패턴 | I11: WBD3L11502 | J11: 러닝
A12: GF1LKP510 | B12: GF7LKP510 | E12: GF7LKP502 | F12: 워셔블 | I12: WBE2L11505 | J12: 러닝
A13: WBE3L05512 | B13: GF7LKP512 | E13: GF7LKP510 | F13: 워셔블 | I13: WBE1L04506 | J13: 러닝
... A15: GF1LTS505 | B15: GF7LTS505 | E15: GF7LPT501 | F15: 마스터 | I15: WBD4L04550 | J15: 러닝
A16: WBE3L01503 | B16: GF7LTS503 | E16: GF3LJP501 | F16: 가죽
A17: WBE1L13505 | B17: GF7LSK505 | E17: GF3LCT508 | F17: 가죽
A18: WBD3L11502 | B18: GF8LPT502 | E18: GF4LCT509 | F18: 아르노
A19: WBE1L12504 | B19: GF7LHP504 | E19: GF3LJP512 | F19: 셋업
A20: WBE3L09502 | B20: GF7LJK502 | E20: GF3LTS505 | F20: 쫀쫀
A21: WBD3L04505 | B21: GF7LKC505 | E21: GF3LTS506 | F21: 쫀쫀
A22: WBE1L04507 | B22: GF7LKC507 | E22: GF3LTS503 | F22: 쫀쫀
A23: WBE3L05504 | B23: GF7LKP504 | E23: GF3LPT502 | F23: 마스터
A24: WBD3L05527 | B24: GF7LKP527 | E24: GF3LPT501 | F24: 마스터
A25: GF1LPT501 | B25: GF7LPT501 | E25: GF3LPT512 | F25: 셋업
A26: WBE1L03507 | B26: GF7LSH507 | E26: GF3LHP501 | F26: 가죽
A27: WBE3L01502 | B27: GF7LTS502 | E27: GF3LSK504 | F27: 가죽
... A37: SBE3U07006 | B37: GF7UJP006 | E37: GF3LKC515 | F37: 셋업
E38: GF3LKC518 | F38: 셋업
E39: GF3LKC517 | F39: 노르딕,패턴
E40: GF3LKC514 | F40: 노르딕,패턴
E41: GF3LKP521 | F41: 노르딕,패턴
E42: GF3LOP515 | F42: 셋업
E43: GF3LOP503 | F43: 가죽
E44: GF3LPT507 | F44: 마스터
E45: GF3LPT518 | F45: 마스터
E46: GF3LPT510 | F46: 플리스
E47: GF7LHP504 | F47: 마스터
E48: GF3LSK518 | F48: 셋업
E49: GF4LJP523 | F49: 패딩
... E112: GF4UET014 | F112: 플리스

Sheet 종합
C1: ※ 26FW 시즌 판매 현황 | AC1: ※ 25FW 시즌 판매 현황
C3: *26FW 시즌별 / 복종 별 | O3: V- | AC3: *25FW 시즌별 / 복종 별 | AO3: V-
C4: 26FW | D4: 구 분 | G4: 기획현황 | J4: 입고현황 | T4: 판매현황 | AC4: 25FW | AD4: 구 분 | AG4: 기획현황 | AJ4: 입고현황 | AT4: 판매현황
D6: 시즌 | E6: 복종 | G6: M | H6: SKU | I6: 기획량 | J6: M | K6: SKU | L6: 입고량 | M6: 입고율 | N6: 기획원가 | O6: 생산원가 | P6: 원가 비중 | Q6: TAG | R6: 택가비중 | S6: M/U | T6: 누계판매량 | U6: 수량판매율 | V6: 누계판매 TAG | W6: 누계실판매 금액 | X6: 누계판매 원가 | Y6: 할인율 | Z6: 주간판매량 | AA6: 주간 판매금액 | AD6: 시즌 | AE6: 복종 | AG6: M | AH6: SKU | AI6: 기획량 | AJ6: M | AK6: SKU | AL6: 입고량 | AM6: 입고율 | AN6: 기획원가 | AO6: 생산원가 | AP6: 원가 비중 | AQ6: TAG | AR6: 택가비중 | AS6: M/U | AT6: 누계판매량 | AU6: 수량판매율 | AV6: 누계판매 TAG | AW6: 누계실판매 금액 | AX6: 누계판매 원가 | AY6: 할인율 | AZ6: 주간판매량 | BA6: 주간 판매금액
D7: 가을 | E7: OUTER | G7: =+G80 -> 30 | H7: =+H80 -> 68 | I7: =+I80 -> 36884 | J7: =+J80 -> 16 | K7: =+K80 -> 36 | L7: =+L80 -> 19310 | M7: =+M80 -> 0.52353324 | N7: =+N80 -> 1189916600 | O7: =+O80 -> 619704560 | P7: =O7/O$17 -> 0.28137556 | Q7: =+Q80 -> 2548228000 | R7: =Q7/Q$17 -> 0.27567007 | S7: =+S80 -> 3.738186 | T7: =+T80 -> 476 | U7: =+U80 -> 0.02465044 | V7: =+V80 -> 43288000 | W7: =+W80 -> 32708199 | X7: =+X80 -> 11266700 | Y7: =+Y80 -> 0.24440494 | Z7: =+Z80 -> 241 | AA7: =+AA80 -> 15975469 | AD7: 가을 | AE7: OUTER | AG7: =+AG80 -> 31 | AH7: =+AH80 -> 0 | AI7: =+AI80 -> 39698 | AJ7: =+AJ80 -> 11 | AK7: =+AK80 -> 0 | AL7: =+AL80 -> 13104 | AM7: =+AM80 -> 0.3300922 | AN7: =+AN80 -> 1341437000 | AO7: =+AO80 -> 314682400 | AP7: =AO7/AO$17 -> 0.14486744 | AQ7: =+AQ80 -> 1341856000 | AR7: =AQ7/AQ$17 -> 0.14326104 | AS7: =+AS80 -> 3.8765088 | AT7: =+AT80 -> 1448 | AU7: =+AU80 -> 0.11050061 | AV7: =+AV80 -> 96465000 | AW7: =+AW80 -> 57524069 | AX7: =+AX80 -> 23002600 | AY7: =+AY80 -> 0.40367938 | AZ7: =+AZ80 -> 534 | BA7: =+BA80 -> 24190146 | BC7: 카테고리
E8: TOP | G8: =+G93 -> 77 | H8: =+H93 -> 207 | I8: =+I93 -> 139621 | J8: =+J93 -> 31 | K8: =+K93 -> 88 | L8: =+L93 -> 74088 | M8: =+M93 -> 0.53063651 | N8: =+N93 -> 1906122400 | O8: =+O93 -> 1028832620 | P8: =O8/O$17 -> 0.4671393 | Q8: =+Q93 -> 4574966000 | R8: =Q8/Q$17 -> 0.49492479 | S8: =+S93 -> 4.042504 | T8: =+T93 -> 4453 | U8: =+U93 -> 0.0601042 | V8: =+V93 -> 283304000 | W8: =+W93 -> 216326359 | X8: =+X93 -> 66043900 | Y8: =+Y93 -> 0.23641615 | Z8: =+Z93 -> 2413 | AA8: =+AA93 -> 116060393 | AE8: TOP | AG8: =+AG93 -> 79 | AH8: =+AH93 -> 0 | AI8: =+AI93 -> 258957 | AJ8: =+AJ93 -> 49 | AK8: =+AK93 -> 0 | AL8: =+AL93 -> 102765 | AM8: =+AM93 -> 0.39684195 | AN8: =+AN93 -> 3538274700 | AO8: =+AO93 -> 1436245460 | AP8: =AO8/AO$17 -> 0.66119108 | AQ8: =+AQ93 -> 6201852000 | AR8: =AQ8/AQ$17 -> 0.66213051 | AS8: =+AS93 -> 3.9255458 | AT8: =+AT93 -> 13100 | AU8: =+AU93 -> 0.12747531 | AV8: =+AV93 -> 677354000 | AW8: =+AW93 -> 429235459 | AX8: =+AX93 -> 154455000 | AY8: =+AY93 -> 0.36630557 | AZ8: =+AZ93 -> 4998 | BA8: =+BA93 -> 168660293 | BC8: INNER (W/O KNIT) | BD8: TOP
E9: BOTTOM | G9: =+G100 -> 43 | H9: =+H100 -> 101 | I9: =+I100 -> 51314 | J9: =+J100 -> 18 | K9: =+K100 -> 40 | L9: =+L100 -> 20593 | M9: =+M100 -> 0.40131348 | N9: =+N100 -> 779552350 | O9: =+O100 -> 400827400 | P9: =O9/O$17 -> 0.18199484 | Q9: =+Q100 -> 1540871000 | R9: =Q9/Q$17 -> 0.1666931 | S9: =+S100 -> 3.4947507 | T9: =+T100 -> 817 | U9: =+U100 -> 0.039673676 | V9: =+V100 -> 58044000 | W9: =+W100 -> 43530122 | X9: =+X100 -> 14356380 | Y9: =+Y100 -> 0.25004958 | Z9: =+Z100 -> 568 | AA9: =+AA100 -> 29602751 | AE9: BOTTOM | AG9: =+AG100 -> 26 | AH9: =+AH100 -> 0 | AI9: =+AI100 -> 57935 | AJ9: =+AJ100 -> 16 | AK9: =+AK100 -> 0 | AL9: =+AL100 -> 22816 | AM9: =+AM100 -> 0.39382066 | AN9: =+AN100 -> 982174000 | AO9: =+AO100 -> 405821300 | AP9: =AO9/AO$17 -> 0.18682421 | AQ9: =+AQ100 -> 1743584000 | AR9: =AQ9/AQ$17 -> 0.18615087 | AS9: =+AS100 -> 3.9058481 | AT9: =+AT100 -> 2438 | AU9: =+AU100 -> 0.10685484 | AV9: =+AV100 -> 185542000 | AW9: =+AW100 -> 103357945 | AX9: =+AX100 -> 42867700 | AY9: =+AY100 -> 0.44294044 | AZ9: =+AZ100 -> 1186 | BA9: =+BA100 -> 45250874 | BC9: KNIT | BD9: TOP
E10: ACC | G10: =+G107 -> 21 | H10: =+H107 -> 48 | I10: =+I107 -> 15407 | J10: =+J107 -> 7 | K10: =+K107 -> 13 | L10: =+L107 -> 9020 | M10: =+M107 -> 0.58544817 | N10: =+N107 -> 44030000 | O10: =+O107 -> 43574200 | P10: =O10/O$17 -> 0.019784774 | Q10: =+Q107 -> 115151000 | R10: =Q10/Q$17 -> 0.01245716 | S10: =+S107 -> 2.4024016 | T10: =+T107 -> 284 | U10: =+U107 -> 0.031485588 | V10: =+V107 -> 2328208 | W10: =+W107 -> 1773804 | X10: =+X107 -> 1274600 | Y10: =+Y107 -> 0.23812477 | Z10: =+Z107 -> 193 | AA10: =+AA107 -> 1659800 | AE10: ACC | AG10: =+AG107 -> 14 | AH10: =+AH107 -> 0 | AI10: =+AI107 -> 8803 | AJ10: =+AJ107 -> 5 | AK10: =+AK107 -> 0 | AL10: =+AL107 -> 2646 | AM10: =+AM107 -> 0.30057935 | AN10: =+AN107 -> 97421425 | AO10: =+AO107 -> 15460200 | AP10: =AO10/AO$17 -> 0.0071172698 | AQ10: =+AQ107 -> 79218000 | AR10: =AQ10/AQ$17 -> 0.0084575792 | AS10: =+AS107 -> 4.658178 | AT10: =+AT107 -> 16 | AU10: =+AU107 -> 0.0060468632 | AV10: =+AV107 -> 432000 | AW10: =+AW107 -> 556920 | AX10: =+AX107 -> 88000 | AY10: =+AY107 -> -0.28916667 | AZ10: =+AZ107 -> 16 | BA10: =+BA107 -> 556920 | BC10: OUTER | BD10: OUTER
E11: TTL | G11: =+G109 -> 171 | H11: =+H109 -> 424 | I11: =+I109 -> 243226 | J11: =+J109 -> 72 | K11: =+K109 -> 177 | L11: =+L109 -> 123011 | M11: =+M109 -> 0.50574774 | N11: =+N109 -> 3919621350 | O11: =+O109 -> 2092938780 | P11: =O11/O$17 -> 0.95029447 | Q11: =+Q109 -> 8779216000 | R11: =Q11/Q$17 -> 0.94974513 | S11: =+S109 -> 3.8133487 | T11: =+T109 -> 6030 | U11: =+U109 -> 0.049020006 | V11: =+V109 -> 386964208 | W11: =+W109 -> 294338484 | X11: =+X109 -> 92941580 | Y11: =+Y109 -> 0.23936509 | Z11: =+Z109 -> 3415 | AA11: =+AA109 -> 163298413 | AE11: TTL | AG11: =+AG109 -> 150 | AH11: =+AH109 -> 0 | AI11: =+AI109 -> 365393 | AJ11: =+AJ109 -> 81 | AK11: =+AK109 -> 0 | AL11: =+AL109 -> 141331 | AM11: =+AM109 -> 0.38679176 | AN11: =+AN109 -> 5959307125 | AO11: =+AO109 -> 2172209360 | AP11: =AO11/AO$17 -> 1 | AQ11: =+AQ109 -> 9366510000 | AR11: =AQ11/AQ$17 -> 1 | AS11: =+AS109 -> 3.9199762 | AT11: =+AT109 -> 17002 | AU11: =+AU109 -> 0.12029916 | AV11: =+AV109 -> 959793000 | AW11: =+AW109 -> 590674393 | AX11: =+AX109 -> 220413300 | AY11: =+AY109 -> 0.38458147 | AZ11: =+AZ109 -> 6734 | BA11: =+BA109 -> 238658233 | BC11: BOTTOM | BD11: BOTTOM
D12: 겨울 | E12: OUTER | G12: =+G121 -> 17 | H12: =+H121 -> 32 | I12: =+I121 -> 22616 | J12: =+J121 -> 2 | K12: =+K121 -> 3 | L12: =+L121 -> 2696 | M12: =+M121 -> 0.11920764 | N12: =+N121 -> 688285000 | O12: =+O121 -> 109472000 | P12: =O12/O$17 -> 0.049705532 | Q12: =+Q121 -> 464544000 | R12: =Q12/Q$17 -> 0.050254875 | S12: =+S121 -> 3.8577237 | T12: =+T121 -> 0 | U12: =+U121 -> 0 | V12: =+V121 -> 0 | W12: =+W121 -> 0 | X12: =+X121 -> 0 | Y12: =+Y121 | Z12: =+Z121 -> 0 | AA12: =+AA121 -> 0 | AD12: 겨울 | AE12: OUTER | AG12: =+AG121 -> 22 | AH12: =+AH121 -> 0 | AI12: =+AI121 -> 34532 | AJ12: =+AJ121 -> 2 | AK12: =+AK121 -> 3 | AL12: =+AL121 -> 0 | AM12: =+AM121 -> 0 | AN12: =+AN121 -> 1556000100 | AO12: =+AO121 -> 0 | AP12: =AO12/AO$17 -> 0 | AQ12: =+AQ121 -> 0 | AR12: =AQ12/AQ$17 -> 0 | AS12: =+AS121 | AT12: =+AT121 -> 0 | AU12: =+AU121 | AV12: =+AV121 -> 0 | AW12: =+AW121 -> 0 | AX12: =+AX121 -> 0 | AY12: =+AY121 | AZ12: =+AZ121 -> 0 | BA12: =+BA121 -> 0 | BC12: SHOES | BD12: ACC
E13: TOP | G13: =+G134 -> 22 | H13: =+H134 -> 52 | I13: =+I134 -> 10116 | J13: =+J134 -> 0 | K13: =+K134 -> 0 | L13: =+L134 -> 0 | M13: =+M134 -> 0 | N13: =+N134 -> 0 | O13: =+O134 -> 0 | P13: =O13/O$17 -> 0 | Q13: =+Q134 -> 0 | R13: =Q13/Q$17 -> 0 | S13: =+S134 | T13: =+T134 -> 0 | U13: =+U134 | V13: =+V134 -> 0 | W13: =+W134 -> 0 | X13: =+X134 -> 0 | Y13: =+Y134 | Z13: =+Z134 -> 0 | AA13: =+AA134 -> 0 | AE13: TOP | AG13: =+AG134 -> 55 | AH13: =+AH134 -> 0 | AI13: =+AI134 -> 110724 | AJ13: =+AJ134 -> 0 | AK13: =+AK134 -> 0 | AL13: =+AL134 -> 0 | AM13: =+AM134 -> 0 | AN13: =+AN134 -> 1745202400 | AO13: =+AO134 -> 0 | AP13: =AO13/AO$17 -> 0 | AQ13: =+AQ134 -> 0 | AR13: =AQ13/AQ$17 -> 0 | AS13: =+AS134 | AT13: =+AT134 -> 0 | AU13: =+AU134 | AV13: =+AV134 -> 0 | AW13: =+AW134 -> 0 | AX13: =+AX134 -> 0 | AY13: =+AY134 | AZ13: =+AZ134 -> 0 | BA13: =+BA134 -> 0 | BC13: ACC | BD13: ACC
E14: BOTTOM | G14: =+G141 -> 2 | H14: =+H141 -> 4 | I14: =+I141 -> 402 | J14: =+J141 -> 0 | K14: =+K141 -> 0 | L14: =+L141 -> 0 | M14: =+M141 -> 0 | N14: =+N141 -> 0 | O14: =+O141 -> 0 | P14: =O14/O$17 -> 0 | Q14: =+Q141 -> 0 | R14: =Q14/Q$17 -> 0 | S14: =+S141 | T14: =+T141 -> 0 | U14: =+U141 | V14: =+V141 -> 0 | W14: =+W141 -> 0 | X14: =+X141 -> 0 | Y14: =+Y141 | Z14: =+Z141 -> 0 | AA14: =+AA141 -> 0 | AE14: BOTTOM | AG14: =+AG141 -> 19 | AH14: =+AH141 -> 0 | AI14: =+AI141 -> 21390 | AJ14: =+AJ141 -> 0 | AK14: =+AK141 -> 0 | AL14: =+AL141 -> 0 | AM14: =+AM141 -> 0 | AN14: =+AN141 -> 389125500 | AO14: =+AO141 -> 0 | AP14: =AO14/AO$17 -> 0 | AQ14: =+AQ141 -> 0 | AR14: =AQ14/AQ$17 -> 0 | AS14: =+AS141 | AT14: =+AT141 -> 0 | AU14: =+AU141 | AV14: =+AV141 -> 0 | AW14: =+AW141 -> 0 | AX14: =+AX141 -> 0 | AY14: =+AY141 | AZ14: =+AZ141 -> 0 | BA14: =+BA141 -> 0 | BC14: 기타 | BD14: ACC
E15: ACC | G15: =+G148 -> 14 | H15: =+H148 -> 26 | I15: =+I148 -> 6956 | J15: =+J148 -> 0 | K15: =+K148 -> 0 | L15: =+L148 -> 0 | M15: =+M148 -> 0 | N15: =+N148 -> 0 | O15: =+O148 -> 0 | P15: =O15/O$17 -> 0 | Q15: =+Q148 -> 0 | R15: =Q15/Q$17 -> 0 | S15: =+S148 | T15: =+T148 -> 0 | U15: =+U148 | V15: =+V148 -> 0 | W15: =+W148 -> 0 | X15: =+X148 -> 0 | Y15: =+Y148 | Z15: =+Z148 -> 0 | AA15: =+AA148 -> 0 | AE15: ACC | AG15: =+AG148 -> 26 | AH15: =+AH148 -> 0 | AI15: =+AI148 -> 16259 | AJ15: =+AJ148 -> 0 | AK15: =+AK148 -> 0 | AL15: =+AL148 -> 0 | AM15: =+AM148 -> 0 | AN15: =+AN148 -> 148207081 | AO15: =+AO148 -> 0 | AP15: =AO15/AO$17 -> 0 | AQ15: =+AQ148 -> 0 | AR15: =AQ15/AQ$17 -> 0 | AS15: =+AS148 | AT15: =+AT148 -> 0 | AU15: =+AU148 | AV15: =+AV148 -> 0 | AW15: =+AW148 -> 0 | AX15: =+AX148 -> 0 | AY15: =+AY148 | AZ15: =+AZ148 -> 0 | BA15: =+BA148 -> 0
E16: TTL | G16: =+G150 -> 55 | H16: =+H150 -> 114 | I16: =+I150 -> 40090 | J16: =+J150 -> 2 | K16: =+K150 -> 3 | L16: =+L150 -> 2696 | M16: =+M150 -> 0.06724869 | N16: =+N150 -> 688285000 | O16: =+O150 -> 109472000 | P16: =O16/O$17 -> 0.049705532 | Q16: =+Q150 -> 464544000 | R16: =Q16/Q$17 -> 0.050254875 | S16: =+S150 -> 3.8577237 | T16: =+T150 -> 0 | U16: =+U150 -> 0 | V16: =+V150 -> 0 | W16: =+W150 -> 0 | X16: =+X150 -> 0 | Y16: =+Y150 | Z16: =+Z150 -> 0 | AA16: =+AA150 -> 0 | AE16: TTL | AG16: =+AG150 -> 122 | AH16: =+AH150 -> 0 | AI16: =+AI150 -> 182905 | AJ16: =+AJ150 -> 2 | AK16: =+AK150 -> 3 | AL16: =+AL150 -> 0 | AM16: =+AM150 -> 0 | AN16: =+AN150 -> 3838535081 | AO16: =+AO150 -> 0 | AP16: =AO16/AO$17 -> 0 | AQ16: =+AQ150 -> 0 | AR16: =AQ16/AQ$17 -> 0 | AS16: =+AS150 | AT16: =+AT150 -> 0 | AU16: =+AU150 | AV16: =+AV150 -> 0 | AW16: =+AW150 -> 0 | AX16: =+AX150 -> 0 | AY16: =+AY150 | AZ16: =+AZ150 -> 0 | BA16: =+BA150 -> 0
C17: TTL | G17: =G66 -> 226 | H17: =H66 -> 538 | I17: =I66 -> 283316 | J17: =J66 -> 74 | K17: =K66 -> 180 | L17: =L66 -> 125707 | M17: =M66 -> 0.44369891 | N17: =N66 -> 4607906350 | O17: =O66 -> 2202410780 | P17: =O17/O$17 -> 1 | Q17: =Q66 -> 9243760000 | R17: =Q17/Q$17 -> 1 | S17: =S66 -> 3.8155544 | T17: =T66 -> 6030 | U17: =U66 -> 0.047968689 | V17: =V66 -> 386964208 | W17: =W66 -> 294338484 | X17: =X66 -> 92941580 | Y17: =Y66 -> 0.23936509 | Z17: =Z66 -> 3415 | AA17: =AA66 -> 163298413 | AC17: TTL | AG17: =AG66 -> 289 | AH17: =AH66 -> 0 | AI17: =AI66 -> 575258 | AJ17: =AJ66 -> 83 | AK17: =AK66 -> 3 | AL17: =AL66 -> 141331 | AM17: =AM66 -> 0.24568281 | AN17: =AN66 -> 10178448706 | AO17: =AO66 -> 2172209360 | AP17: =AO17/AO$17 -> 1 | AQ17: =AQ66 -> 9366510000 | AR17: =AQ17/AQ$17 -> 1 | AS17: =AS66 -> 3.9199762 | AT17: =AT66 -> 17002 | AU17: =AU66 -> 0.12029916 | AV17: =AV66 -> 959793000 | AW17: =AW66 -> 590674393 | AX17: =AX66 -> 220413300 | AY17: =AY66 -> 0.38458147 | AZ17: =AZ66 -> 6734 | BA17: =BA66 -> 238658233
C18: 러닝 | E18: OUTER | G18: =J18 -> 9 | J18: =BH37 -> 9 | L18: =BM37 -> 29282 | O18: =BP37 -> 1125334070 | Q18: =BR37 -> 4833065000 | S18: =IFERROR(Q18/O18/1.1,"") -> 3.9043477 | T18: =BU37 -> 1721 | U18: =IFERROR(T18/L18,"") -> 0.058773308 | V18: =BW37 -> 85558000 | W18: =BX37 -> 68696304 | X18: =BY37 -> 23220250 | Y18: =IFERROR(1-(W18/V18),"") -> 0.19707913 | Z18: =CA37 -> 1211 | AA18: =CB37 -> 48958180 | AC18: 러닝 | AE18: OUTER | AG18: =AJ18 -> 1 | AJ18: =COUNTIFS('전년비교BACK(전년8.1~동시점,생판재)'!$F$4:$F$5000,종합!$BC10,'전년비교BACK(전년8.1~동시점,생판재)'!$BR$4:$BR$5000,종합!$AC$18) -> 1 | AL18: =SUMIFS('전년비교BACK(전년8.1~동시점,생판재)'!$AP$4:$AP$5000,'전년비교BACK(전년8.1~동시점,생판재)'!$F$4:$F$5000,종합!$BC$10,'전년비교BACK(전년8.1~동시점,생판재)'!$BR$4:$BR$5000,종합!$C$18) -> 1651 | AS18: =IFERROR(AQ18/AO18/1.1,"") | AT18: =SUMIFS('전년비교BACK(전년8.1~동시점,생판재)'!$BG$4:$BG$5000,'전년비교BACK(전년8.1~동시점,생판재)'!$F$4:$F$5000,종합!$BC$10,'전년비교BACK(전년8.1~동시점,생판재)'!$BR$4:$BR$5000,종합!$C$18)- SUMIFS('시점재고(~25.07.31, 생판재)'!$BG$4:$BG$5000,'시점재고(~25.07.31, 생판재)'!$F$4:$F$5000,종합!$BC$10,'시점재고(~25.07.31, 생판재)'!$BR$4:$BR$5000,종합!$C$18) -> 13 | AU18: =IFERROR(AT18/AL18,"") -> 0.0078740157 | AV18: =SUMIFS('전년비교BACK(전년8.1~동시점,생판재)'!$BH$4:$BH$5000,'전년비교BACK(전년8.1~동시점,생판재)'!$F$4:$F$5000,종합!$BC$10,'전년비교BACK(전년8.1~동시점,생판재)'!$BR$4:$BR$5000,종합!$C$18)- SUMIFS('시점재고(~25.07.31, 생판재)'!$BH$4:$BH$5000,'시점재고(~25.07.31, 생판재)'!$F$4:$F$5000,종합!$BC$10,'시점재고(~25.07.31, 생판재)'!$BR$4:$BR$5000,종합!$C$18) -> 1287000 | AW18: =SUMIFS('전년비교BACK(전년8.1~동시점,생판재)'!$BI$4:$BI$5000,'전년비교BACK(전년8.1~동시점,생판재)'!$F$4:$F$5000,종합!$BC$10,'전년비교BACK(전년8.1~동시점,생판재)'!$BR$4:$BR$5000,종합!$C$18)- SUMIFS('시점재고(~25.07.31, 생판재)'!$BI$4:$BI$5000,'시점재고(~25.07.31, 생판재)'!$F$4:$F$5000,종합!$BC$10,'시점재고(~25.07.31, 생판재)'!$BR$4:$BR$5000,종합!$C$18) -> 767065 | AY18: =IFERROR(1-(AW18/AV18),"") -> 0.4039899 | AZ18: =SUMIFS('전년비교BACK(전년8.1~동시점,생판재)'!$BC$4:$BC$5000,'전년비교BACK(전년8.1~동시점,생판재)'!$F$4:$F$5000,종합!$BC$10,'전년비교BACK(전년8.1~동시점,생판재)'!$BR$4:$BR$5000,종합!$C$18) -> 5 | BA18: =SUMIFS('전년비교BACK(전년8.1~동시점,생판재)'!$BE$4:$BE$5000,'전년비교BACK(전년8.1~동시점,생판재)'!$F$4:$F$5000,종합!$BC$10,'전년비교BACK(전년8.1~동시점,생판재)'!$BR$4:$BR$5000,종합!$C$18) -> 331810
E19: TOP | G19: =J19 -> 19 | J19: =BH50 -> 19 | L19: =BM50 -> 124868 | O19: =BP50 -> 1839254880 | Q19: =BR50 -> 8362760000 | S19: =IFERROR(Q19/O19/1.1,"") -> 4.1334723 | T19: =BU50 -> 4378 | U19: =IFERROR(T19/L19,"") -> 0.035061024 | V19: =BW50 -> 282673000 | W19: =BX50 -> 172120770 | X19: =BY50 -> 59898580 | Y19: =IFERROR(1-(W19/V19),"") -> 0.39109582 | Z19: =CA50 -> 2125 | AA19: =CB50 -> 85153996 | AE19: TOP | AG19: =AJ19 -> 10 | AJ19: =COUNTIFS('전년비교BACK(전년8.1~동시점,생판재)'!$F$4:$F$5000,종합!$BC8,'전년비교BACK(전년8.1~동시점,생판재)'!$BR$4:$BR$5000,종합!$AC$18)+COUNTIFS('전년비교BACK(전년8.1~동시점,생판재)'!$F$4:$F$5000,종합!$BC9,'전년비교BACK(전년8.1~동시점,생판재)'!$BR$4:$BR$5000,종합!$AC$18) -> 10 | AL19: =SUMIFS('전년비교BACK(전년8.1~동시점,생판재)'!$AP$4:$AP$5000,'전년비교BACK(전년8.1~동시점,생판재)'!$F$4:$F$5000,종합!$BC$9,'전년비교BACK(전년8.1~동시점,생판재)'!$BR$4:$BR$5000,종합!$C$18)+ SUMIFS('전년비교BACK(전년8.1~동시점,생판재)'!$AP$4:$AP$5000,'전년비교BACK(전년8.1~동시점,생판재)'!$F$4:$F$5000,종합!$BC$8,'전년비교BACK(전년8.1~동시점,생판재)'!$BR$4:$BR$5000,종합!$C$18) -> 443495 | AS19: =IFERROR(AQ19/AO19/1.1,"") | AT19: =SUMIFS('전년비교BACK(전년8.1~동시점,생판재)'!$BG$4:$BG$5000,'전년비교BACK(전년8.1~동시점,생판재)'!$F$4:$F$5000,종합!$BC$9,'전년비교BACK(전년8.1~동시점,생판재)'!$BR$4:$BR$5000,종합!$C$18)+ SUMIFS('전년비교BACK(전년8.1~동시점,생판재)'!$BG$4:$BG$5000,'전년비교BACK(전년8.1~동시점,생판재)'!$F$4:$F$5000,종합!$BC$8,'전년비교BACK(전년8.1~동시점,생판재)'!$BR$4:$BR$5000,종합!$C$18)-( SUMIFS('시점재고(~25.07.31, 생판재)'!$BG$4:$BG$5000,'시점재고(~25.07.31, 생판재)'!$F$4:$F$5000,종합!$BC$9,'시점재고(~25.07.31, 생판재)'!$BR$4:$BR$5000,종합!$C$18)+ SUMIFS('시점재고(~25.07.31, 생판재)'!$BG$4:$BG$5000,'시점재고(~25.07.31, 생판재)'!$F$4:$F$5000,종합!$BC$8,'시점재고(~25.07.31, 생판재)'!$BR$4:$BR$5000,종합!$C$18)) -> 9845 | AU19: =IFERROR(AT19/AL19,"") -> 0.022198672 | AV19: =SUMIFS('전년비교BACK(전년8.1~동시점,생판재)'!$BH$4:$BH$5000,'전년비교BACK(전년8.1~동시점,생판재)'!$F$4:$F$5000,종합!$BC$9,'전년비교BACK(전년8.1~동시점,생판재)'!$BR$4:$BR$5000,종합!$C$18)+ SUMIFS('전년비교BACK(전년8.1~동시점,생판재)'!$BH$4:$BH$5000,'전년비교BACK(전년8.1~동시점,생판재)'!$F$4:$F$5000,종합!$BC$8,'전년비교BACK(전년8.1~동시점,생판재)'!$BR$4:$BR$5000,종합!$C$18)-( SUMIFS('시점재고(~25.07.31, 생판재)'!$BH$4:$BH$5000,'시점재고(~25.07.31, 생판재)'!$F$4:$F$5000,종합!$BC$9,'시점재고(~25.07.31, 생판재)'!$BR$4:$BR$5000,종합!$C$18)+ SUMIFS('시점재고(~25.07.31, 생판재)'!$BH$4:$BH$5000,'시점재고(~25.07.31, 생판재)'!$F$4:$F$5000,종합!$BC$8,'시점재고(~25.07.31, 생판재)'!$BR$4:$BR$5000,종합!$C$18)) -> 774041000 | AW19: =SUMIFS('전년비교BACK(전년8.1~동시점,생판재)'!$BI$4:$BI$5000,'전년비교BACK(전년8.1~동시점,생판재)'!$F$4:$F$5000,종합!$BC$9,'전년비교BACK(전년8.1~동시점,생판재)'!$BR$4:$BR$5000,종합!$C$18)+ SUMIFS('전년비교BACK(전년8.1~동시점,생판재)'!$BI$4:$BI$5000,'전년비교BACK(전년8.1~동시점,생판재)'!$F$4:$F$5000,종합!$BC$8,'전년비교BACK(전년8.1~동시점,생판재)'!$BR$4:$BR$5000,종합!$C$18)-( SUMIFS('시점재고(~25.07.31, 생판재)'!$BI$4:$BI$5000,'시점재고(~25.07.31, 생판재)'!$F$4:$F$5000,종합!$BC$9,'시점재고(~25.07.31, 생판재)'!$BR$4:$BR$5000,종합!$C$18)+ SUMIFS('시점재고(~25.07.31, 생판재)'!$BI$4:$BI$5000,'시점재고(~25.07.31, 생판재)'!$F$4:$F$5000,종합!$BC$8,'시점재고(~25.07.31, 생판재)'!$BR$4:$BR$5000,종합!$C$18)) -> 365612555 | AY19: =IFERROR(1-(AW19/AV19),"") -> 0.52765738 | AZ19: =SUMIFS('전년비교BACK(전년8.1~동시점,생판재)'!$BC$4:$BC$5000,'전년비교BACK(전년8.1~동시점,생판재)'!$F$4:$F$5000,종합!$BC$9,'전년비교BACK(전년8.1~동시점,생판재)'!$BR$4:$BR$5000,종합!$C$18)+ SUMIFS('전년비교BACK(전년8.1~동시점,생판재)'!$BC$4:$BC$5000,'전년비교BACK(전년8.1~동시점,생판재)'!$F$4:$F$5000,종합!$BC$8,'전년비교BACK(전년8.1~동시점,생판재)'!$BR$4:$BR$5000,종합!$C$18) -> 4179 | BA19: =SUMIFS('전년비교BACK(전년8.1~동시점,생판재)'!$BE$4:$BE$5000,'전년비교BACK(전년8.1~동시점,생판재)'!$F$4:$F$5000,종합!$BC$9,'전년비교BACK(전년8.1~동시점,생판재)'!$BR$4:$BR$5000,종합!$C$18)+ SUMIFS('전년비교BACK(전년8.1~동시점,생판재)'!$BE$4:$BE$5000,'전년비교BACK(전년8.1~동시점,생판재)'!$F$4:$F$5000,종합!$BC$8,'전년비교BACK(전년8.1~동시점,생판재)'!$BR$4:$BR$5000,종합!$C$18) -> 159940419
E20: BOTTOM | G20: =J20 -> 8 | J20: =BH57 -> 8 | L20: =BM57 -> 5435 | O20: =BP57 -> 98885900 | Q20: =BR57 -> 398751000 | S20: =IFERROR(Q20/O20/1.1,"") -> 3.6658503 | T20: =BU57 -> 190 | U20: =IFERROR(T20/L20,"") -> 0.034958602 | V20: =BW57 -> 13848000 | W20: =BX57 -> 9749230 | X20: =BY57 -> 3365800 | Y20: =IFERROR(1-(W20/V20),"") -> 0.29598281 | Z20: =CA57 -> 96 | AA20: =CB57 -> 5006700 | AE20: BOTTOM | AG20: =AJ20 -> 3 | AJ20: =COUNTIFS('전년비교BACK(전년8.1~동시점,생판재)'!$F$4:$F$5000,종합!$BC11,'전년비교BACK(전년8.1~동시점,생판재)'!$BR$4:$BR$5000,종합!$AC$18) -> 3 | AL20: =SUMIFS('전년비교BACK(전년8.1~동시점,생판재)'!$AP$4:$AP$5000,'전년비교BACK(전년8.1~동시점,생판재)'!$F$4:$F$5000,종합!$BC$11,'전년비교BACK(전년8.1~동시점,생판재)'!$BR$4:$BR$5000,종합!$C$18) -> 28619 | AS20: =IFERROR(AQ20/AO20/1.1,"") | AT20: =SUMIFS('전년비교BACK(전년8.1~동시점,생판재)'!$BG$4:$BG$5000,'전년비교BACK(전년8.1~동시점,생판재)'!$F$4:$F$5000,종합!$BC$11,'전년비교BACK(전년8.1~동시점,생판재)'!$BR$4:$BR$5000,종합!$C$18)- SUMIFS('시점재고(~25.07.31, 생판재)'!$BG$4:$BG$5000,'시점재고(~25.07.31, 생판재)'!$F$4:$F$5000,종합!$BC$11,'시점재고(~25.07.31, 생판재)'!$BR$4:$BR$5000,종합!$C$18) -> 2140 | AU20: =IFERROR(AT20/AL20,"") -> 0.074775499 | AV20: =SUMIFS('전년비교BACK(전년8.1~동시점,생판재)'!$BH$4:$BH$5000,'전년비교BACK(전년8.1~동시점,생판재)'!$F$4:$F$5000,종합!$BC$11,'전년비교BACK(전년8.1~동시점,생판재)'!$BR$4:$BR$5000,종합!$C$18)- SUMIFS('시점재고(~25.07.31, 생판재)'!$BH$4:$BH$5000,'시점재고(~25.07.31, 생판재)'!$F$4:$F$5000,종합!$BC$11,'시점재고(~25.07.31, 생판재)'!$BR$4:$BR$5000,종합!$C$18) -> 129802000 | AW20: =SUMIFS('전년비교BACK(전년8.1~동시점,생판재)'!$BI$4:$BI$5000,'전년비교BACK(전년8.1~동시점,생판재)'!$F$4:$F$5000,종합!$BC$11,'전년비교BACK(전년8.1~동시점,생판재)'!$BR$4:$BR$5000,종합!$C$18)- SUMIFS('시점재고(~25.07.31, 생판재)'!$BI$4:$BI$5000,'시점재고(~25.07.31, 생판재)'!$F$4:$F$5000,종합!$BC$11,'시점재고(~25.07.31, 생판재)'!$BR$4:$BR$5000,종합!$C$18) -> 73239882 | AY20: =IFERROR(1-(AW20/AV20),"") -> 0.43575691 | AZ20: =SUMIFS('전년비교BACK(전년8.1~동시점,생판재)'!$BC$4:$BC$5000,'전년비교BACK(전년8.1~동시점,생판재)'!$F$4:$F$5000,종합!$BC$11,'전년비교BACK(전년8.1~동시점,생판재)'!$BR$4:$BR$5000,종합!$C$18) -> 361 | BA20: =SUMIFS('전년비교BACK(전년8.1~동시점,생판재)'!$BE$4:$BE$5000,'전년비교BACK(전년8.1~동시점,생판재)'!$F$4:$F$5000,종합!$BC$11,'전년비교BACK(전년8.1~동시점,생판재)'!$BR$4:$BR$5000,종합!$C$18) -> 12900719
E21: ACC | G21: =J21 -> 0 | J21: =BH64 -> 0 | L21: =BM64 -> 0 | O21: =BP64 -> 0 | Q21: =BR64 -> 0 | S21: =IFERROR(Q21/O21/1.1,"") | T21: =BU64 -> 0 | U21: =IFERROR(T21/L21,"") | V21: =BW64 -> 0 | W21: =BX64 -> 0 | X21: =BY64 -> 0 | Y21: =IFERROR(1-(W21/V21),"") | Z21: =CA64 -> 0 | AA21: =CB64 -> 0 | AE21: ACC | AG21: =AJ21 -> 0 | AJ21: =COUNTIFS('전년비교BACK(전년8.1~동시점,생판재)'!$F$4:$F$5000,종합!$BC13,'전년비교BACK(전년8.1~동시점,생판재)'!$BR$4:$BR$5000,종합!$AC$18)+ COUNTIFS('전년비교BACK(전년8.1~동시점,생판재)'!$F$4:$F$5000,종합!$BC14,'전년비교BACK(전년8.1~동시점,생판재)'!$BR$4:$BR$5000,종합!$AC$18)+ COUNTIFS('전년비교BACK(전년8.1~동시점,생판재)'!$F$4:$F$5000,종합!$BC12,'전년비교BACK(전년8.1~동시점,생판재)'!$BR$4:$BR$5000,종합!$AC$18) -> 0 | AL21: =SUMIFS('전년비교BACK(전년8.1~동시점,생판재)'!$AP$4:$AP$5000,'전년비교BACK(전년8.1~동시점,생판재)'!$F$4:$F$5000,종합!$BC$13,'전년비교BACK(전년8.1~동시점,생판재)'!$BR$4:$BR$5000,종합!$C$18)+ SUMIFS('전년비교BACK(전년8.1~동시점,생판재)'!$AP$4:$AP$5000,'전년비교BACK(전년8.1~동시점,생판재)'!$F$4:$F$5000,종합!$BC$14,'전년비교BACK(전년8.1~동시점,생판재)'!$BR$4:$BR$5000,종합!$C$18)+ SUMIFS('전년비교BACK(전년8.1~동시점,생판재)'!$AP$4:$AP$5000,'전년비교BACK(전년8.1~동시점,생판재)'!$F$4:$F$5000,종합!$BC$12,'전년비교BACK(전년8.1~동시점,생판재)'!$BR$4:$BR$5000,종합!$C$18) -> 0 | AS21: =IFERROR(AQ21/AO21/1.1,"") | AT21: =SUMIFS('전년비교BACK(전년8.1~동시점,생판재)'!$BG$4:$BG$5000,'전년비교BACK(전년8.1~동시점,생판재)'!$F$4:$F$5000,종합!$BC$13,'전년비교BACK(전년8.1~동시점,생판재)'!$BR$4:$BR$5000,종합!$C$18)+ SUMIFS('전년비교BACK(전년8.1~동시점,생판재)'!$BG$4:$BG$5000,'전년비교BACK(전년8.1~동시점,생판재)'!$F$4:$F$5000,종합!$BC$14,'전년비교BACK(전년8.1~동시점,생판재)'!$BR$4:$BR$5000,종합!$C$18)+ SUMIFS('전년비교BACK(전년8.1~동시점,생판재)'!$BG$4:$BG$5000,'전년비교BACK(전년8.1~동시점,생판재)'!$F$4:$F$5000,종합!$BC$12,'전년비교BACK(전년8.1~동시점,생판재)'!$BR$4:$BR$5000,종합!$C$18)-( SUMIFS('시점재고(~25.07.31, 생판재)'!$BG$4:$BG$5000,'시점재고(~25.07.31, 생판재)'!$F$4:$F$5000,종합!$BC$13,'시점재고(~25.07.31, 생판재)'!$BR$4:$BR$5000,종합!$C$18)+ SUMIFS('시점재고(~25.07.31, 생판재)'!$BG$4:$BG$5000,'시점재고(~25.07.31, 생판재)'!$F$4:$F$5000,종합!$BC$14,'시점재고(~25.07.31, 생판재)'!$BR$4:$BR$5000,종합!$C$18)+ SUMIFS('시점재고(~25.07.31, 생판재)'!$BG$4:$BG$5000,'시점재고(~25.07.31, 생판재)'!$F$4:$F$5000,종합!$BC$12,'시점재고(~25.07.31, 생판재)'!$BR$4:$BR$5000,종합!$C$18)) -> 0 | AU21: =IFERROR(AT21/AL21,"") | AV21: =SUMIFS('전년비교BACK(전년8.1~동시점,생판재)'!$BH$4:$BH$5000,'전년비교BACK(전년8.1~동시점,생판재)'!$F$4:$F$5000,종합!$BC$13,'전년비교BACK(전년8.1~동시점,생판재)'!$BR$4:$BR$5000,종합!$C$18)+ SUMIFS('전년비교BACK(전년8.1~동시점,생판재)'!$BH$4:$BH$5000,'전년비교BACK(전년8.1~동시점,생판재)'!$F$4:$F$5000,종합!$BC$14,'전년비교BACK(전년8.1~동시점,생판재)'!$BR$4:$BR$5000,종합!$C$18)+ SUMIFS('전년비교BACK(전년8.1~동시점,생판재)'!$BH$4:$BH$5000,'전년비교BACK(전년8.1~동시점,생판재)'!$F$4:$F$5000,종합!$BC$12,'전년비교BACK(전년8.1~동시점,생판재)'!$BR$4:$BR$5000,종합!$C$18)-( SUMIFS('시점재고(~25.07.31, 생판재)'!$BH$4:$BH$5000,'시점재고(~25.07.31, 생판재)'!$F$4:$F$5000,종합!$BC$13,'시점재고(~25.07.31, 생판재)'!$BR$4:$BR$5000,종합!$C$18)+ SUMIFS('시점재고(~25.07.31, 생판재)'!$BH$4:$BH$5000,'시점재고(~25.07.31, 생판재)'!$F$4:$F$5000,종합!$BC$14,'시점재고(~25.07.31, 생판재)'!$BR$4:$BR$5000,종합!$C$18)+ SUMIFS('시점재고(~25.07.31, 생판재)'!$BH$4:$BH$5000,'시점재고(~25.07.31, 생판재)'!$F$4:$F$5000,종합!$BC$12,'시점재고(~25.07.31, 생판재)'!$BR$4:$BR$5000,종합!$C$18)) -> 0 | AW21: =SUMIFS('전년비교BACK(전년8.1~동시점,생판재)'!$BI$4:$BI$5000,'전년비교BACK(전년8.1~동시점,생판재)'!$F$4:$F$5000,종합!$BC$13,'전년비교BACK(전년8.1~동시점,생판재)'!$BR$4:$BR$5000,종합!$C$18)+ SUMIFS('전년비교BACK(전년8.1~동시점,생판재)'!$BI$4:$BI$5000,'전년비교BACK(전년8.1~동시점,생판재)'!$F$4:$F$5000,종합!$BC$14,'전년비교BACK(전년8.1~동시점,생판재)'!$BR$4:$BR$5000,종합!$C$18)+ SUMIFS('전년비교BACK(전년8.1~동시점,생판재)'!$BI$4:$BI$5000,'전년비교BACK(전년8.1~동시점,생판재)'!$F$4:$F$5000,종합!$BC$12,'전년비교BACK(전년8.1~동시점,생판재)'!$BR$4:$BR$5000,종합!$C$18)-( SUMIFS('시점재고(~25.07.31, 생판재)'!$BI$4:$BI$5000,'시점재고(~25.07.31, 생판재)'!$F$4:$F$5000,종합!$BC$13,'시점재고(~25.07.31, 생판재)'!$BR$4:$BR$5000,종합!$C$18)+ SUMIFS('시점재고(~25.07.31, 생판재)'!$BI$4:$BI$5000,'시점재고(~25.07.31, 생판재)'!$F$4:$F$5000,종합!$BC$14,'시점재고(~25.07.31, 생판재)'!$BR$4:$BR$5000,종합!$C$18)+ SUMIFS('시점재고(~25.07.31, 생판재)'!$BI$4:$BI$5000,'시점재고(~25.07.31, 생판재)'!$F$4:$F$5000,종합!$BC$12,'시점재고(~25.07.31, 생판재)'!$BR$4:$BR$5000,종합!$C$18)) -> 0 | AY21: =IFERROR(1-(AW21/AV21),"") | AZ21: =SUMIFS('전년비교BACK(전년8.1~동시점,생판재)'!$BC$4:$BC$5000,'전년비교BACK(전년8.1~동시점,생판재)'!$F$4:$F$5000,종합!$BC$13,'전년비교BACK(전년8.1~동시점,생판재)'!$BR$4:$BR$5000,종합!$C$18)+ SUMIFS('전년비교BACK(전년8.1~동시점,생판재)'!$BC$4:$BC$5000,'전년비교BACK(전년8.1~동시점,생판재)'!$F$4:$F$5000,종합!$BC$14,'전년비교BACK(전년8.1~동시점,생판재)'!$BR$4:$BR$5000,종합!$C$18)+ SUMIFS('전년비교BACK(전년8.1~동시점,생판재)'!$BC$4:$BC$5000,'전년비교BACK(전년8.1~동시점,생판재)'!$F$4:$F$5000,종합!$BC$12,'전년비교BACK(전년8.1~동시점,생판재)'!$BR$4:$BR$5000,종합!$C$18) -> 0 | BA21: =SUMIFS('전년비교BACK(전년8.1~동시점,생판재)'!$BE$4:$BE$5000,'전년비교BACK(전년8.1~동시점,생판재)'!$F$4:$F$5000,종합!$BC$13,'전년비교BACK(전년8.1~동시점,생판재)'!$BR$4:$BR$5000,종합!$C$18)+ SUMIFS('전년비교BACK(전년8.1~동시점,생판재)'!$BE$4:$BE$5000,'전년비교BACK(전년8.1~동시점,생판재)'!$F$4:$F$5000,종합!$BC$14,'전년비교BACK(전년8.1~동시점,생판재)'!$BR$4:$BR$5000,종합!$C$18)+ SUMIFS('전년비교BACK(전년8.1~동시점,생판재)'!$BE$4:$BE$5000,'전년비교BACK(전년8.1~동시점,생판재)'!$F$4:$F$5000,종합!$BC$12,'전년비교BACK(전년8.1~동시점,생판재)'!$BR$4:$BR$5000,종합!$C$18) -> 0
E22: TTL | G22: =J22 -> 36 | J22: =SUM(J18:J21) -> 36 | L22: =SUM(L18:L21) -> 159585 | O22: =SUM(O18:O21) -> 3063474850 | Q22: =SUM(Q18:Q21) -> 13594576000 | S22: =IFERROR(Q22/O22/1.1,"") -> 4.0342115 | T22: =SUM(T18:T21) -> 6289 | U22: =IFERROR(T22/L22,"") -> 0.039408466 | V22: =SUM(V18:V21) -> 382079000 | W22: =SUM(W18:W21) -> 250566304 | X22: =SUM(X18:X21) -> 86484630 | Y22: =IFERROR(1-(W22/V22),"") -> 0.34420289 | Z22: =SUM(Z18:Z21) -> 3432 | AA22: =SUM(AA18:AA21) -> 139118876 | AE22: TTL | AG22: =AJ22 -> 14 | AJ22: =SUM(AJ18:AJ21) -> 14 | AL22: =SUM(AL18:AL21) -> 473765 | AO22: =SUM(AO18:AO21) -> 0 | AQ22: =SUM(AQ18:AQ21) -> 0 | AS22: =IFERROR(AQ22/AO22/1.1,"") | AT22: =SUM(AT18:AT21) -> 11998 | AU22: =IFERROR(AT22/AL22,"") -> 0.025324792 | AV22: =SUM(AV18:AV21) -> 905130000 | AW22: =SUM(AW18:AW21) -> 439619502 | AX22: =SUM(AX18:AX21) -> 0 | AY22: =IFERROR(1-(AW22/AV22),"") -> 0.51430236 | AZ22: =SUM(AZ18:AZ21) -> 4545 | BA22: =SUM(BA18:BA21) -> 173172948
C23: TTL | J23: =+J17+J22 -> 110 | L23: =+L17+L22 -> 285292 | O23: =+O17+O22 -> 5265885630 | Q23: =+Q17+Q22 -> 22838336000 | S23: =IFERROR(Q23/O23/1.1,"") -> 3.9427601 | T23: =+T17+T22 -> 12319 | U23: =IFERROR(T23/L23,"") -> 0.043180321 | V23: =+V17+V22 -> 769043208 | W23: =+W17+W22 -> 544904788 | X23: =+X17+X22 -> 179426210 | Y23: =IFERROR(1-(W23/V23),"") -> 0.29145101 | Z23: =+Z17+Z22 -> 6847 | AA23: =+AA17+AA22 -> 302417289 | AC23: TTL | AJ23: =+AJ17+AJ22 -> 97 | AL23: =+AL17+AL22 -> 615096 | AO23: =+AO17+AO22 -> 2172209360 | AQ23: =+AQ17+AQ22 -> 9366510000 | AS23: =IFERROR(AQ23/AO23/1.1,"") -> 3.9199762 | AT23: =+AT17+AT22 -> 29000 | AU23: =IFERROR(AT23/AL23,"") -> 0.047147112 | AV23: =+AV17+AV22 -> 1864923000 | AW23: =+AW17+AW22 -> 1030293895 | AX23: =+AX17+AX22 -> 220413300 | AY23: =IFERROR(1-(AW23/AV23),"") -> 0.44754079 | AZ23: =+AZ17+AZ22 -> 11279 | BA23: =+BA17+BA22 -> 411831181
J24: 26FW 기획 | L24: 26FW 기획 (대시보드에서 구품번과 합산) | O24: 26FW 기획 | Q24: 26FW 기획 | T24: 26FW 기획 (대시보드에서 구품번과 합산) | V24: 26FW 기획 (대시보드에서 구품번과 합산) | W24: 26FW 기획 (대시보드에서 구품번과 합산) | Z24: 26FW 기획 (대시보드에서 구품번과 합산) | AA24: 26FW 기획 (대시보드에서 구품번과 합산) | AL24: 25FW 러닝기획 + 이월재고 | AT24: 누계 25.08.01~
C25: *26FW 신상품 카테고리별 | AC25: *25FW 신상품 카테고리별 | BD25: *26FW 러닝 복종/카테고리별 | CD25: *26FW 러닝 시점재고 판매(8/1~ )
B26: 주간판매 | C26: 26FW | D26: 구 분 | G26: 기획현황 | J26: 입고현황 | T26: 판매현황 | AD26: 구 분 | AG26: 기획현황 | AJ26: 입고현황 | AT26: 판매현황 | BD26: 26FW | BE26: 구 분 | BH26: 기획현황 | BK26: 입고현황 | BU26: 판매현황 | CD26: 시점재고 | CE26: 구 분 | CH26: 시점 | CK26: 판매현황
B27: 생판재
B28: 함수 | D28: 복종 | E28: 카테고리 | F28: 카테고리명 | G28: M | H28: SKU | I28: 기획량 | J28: M | K28: SKU | L28: 입고량 | M28: 입고율 | N28: 기획원가 | O28: 생산원가 | P28: 원가 비중 | Q28: TAG | R28: 택가비중 | S28: M/U | T28: 누계판매량 | U28: 수량판매율 | V28: 누계판매 TAG | W28: 누계실판매 금액 | X28: 누계판매 원가 | Y28: 할인율 | Z28: 주간판매량 | AA28: 주간 판매금액 | AD28: 복종 | AE28: 카테고리 | AF28: 카테고리명 | AG28: M | AH28: SKU | AI28: 기획량 | AJ28: M | AK28: SKU | AL28: 입고량 | AM28: 입고율 | AN28: 기획원가 | AO28: 생산원가 | AP28: 원가 비중 | AQ28: TAG | AR28: 택가비중 | AS28: M/U | AT28: 누계판매량 | AU28: 수량판매율 | AV28: 누계판매 TAG | AW28: 누계실판매 금액 | AX28: 누계판매 원가 | AY28: 할인율 | AZ28: 주간판매량 | BA28: 주간 판매금액 | BE28: 복종 | BF28: 카테고리 | BG28: 카테고리명 | BH28: M | BI28: SKU | BJ28: 기획량 | BK28: M | BL28: SKU | BM28: 입고량 | BN28: 입고율 | BO28: 기획원가 | BP28: 생산원가 | BQ28: 원가 비중 | BR28: TAG | BS28: 택가비중 | BT28: M/U | BU28: 누계판매량 | BV28: 수량판매율 | BW28: 누계판매 TAG | BX28: 누계실판매 금액 | BY28: 누계판매 원가 | BZ28: 할인율 | CA28: 주간판매량 | CB28: 주간 판매금액 | CE28: 복종 | CF28: 카테고리 | CG28: 카테고리명 | CH28: M | CI28: SKU | CJ28: 시점재고 | CK28: 누계판매량 | CL28: 수량판매율 | CM28: 누계판매 TAG | CN28: 누계실판매 금액 | CO28: 누계판매 원가 | CP28: 할인율 | CQ28: 주간판매량 | CR28: 주간 판매금액
D30: OUTER | E30: CT | F30: 코트 | G30: =SUMIF('주간판매-26FW(CO)'!$I:$I,종합!$F30,'주간판매-26FW(CO)'!$P:$P) -> 8 | H30: =COUNTIF('주간판매-26FW(CO)'!$I:$I,종합!$F30) -> 17 | I30: =SUMIFS('주간판매-26FW(CO)'!$R$4:$R$5000,'주간판매-26FW(CO)'!$I$4:$I$5000,종합!$F30) -> 14000 | J30: =SUMIFS('주간판매-26FW(CO)'!$P$4:$P$5000,'주간판매-26FW(CO)'!$I$4:$I$5000,종합!$F30,'주간판매-26FW(CO)'!$V$4:$V$5000,">0") -> 1 | K30: =COUNTIFS('주간판매-26FW(CO)'!$I$4:$I$5000,종합!$F30,'주간판매-26FW(CO)'!$V$4:$V$5000,">0") -> 2 | L30: =SUMIFS('주간판매-26FW(CO)'!$V$4:$V$5000,'주간판매-26FW(CO)'!$I$4:$I$5000,종합!$F30) -> 1329 | M30: =IFERROR(L30/I30,"") -> 0.094928571 | N30: =SUMIFS('생판재-26FW(ST)'!$AI$4:$AI$5000,'생판재-26FW(ST)'!$H$4:$H$5000,종합!$F30) -> 509510000 | O30: =SUMIFS('생판재-26FW(ST)'!$AR$4:$AR$5000,'생판재-26FW(ST)'!$H$4:$H$5000,종합!$F30) -> 60735300 | P30: =O30/O$66 -> 0.027576736 | Q30: =SUMIFS('생판재-26FW(ST)'!$AQ$4:$AQ$5000,'생판재-26FW(ST)'!$H$4:$H$5000,종합!$F30) -> 224601000 | R30: =Q30/Q$66 -> 0.02429758 | S30: =IFERROR(Q30/O30/1.1,"") -> 3.361846 | T30: =SUMIFS('생판재-26FW(ST)'!$BG$4:$BG$5000,'생판재-26FW(ST)'!$H$4:$H$5000,종합!$F30) -> 0 | U30: =IFERROR(T30/L30,"") -> 0 | V30: =SUMIFS('생판재-26FW(ST)'!$BH$4:$BH$5000,'생판재-26FW(ST)'!$H$4:$H$5000,종합!$F30) -> 0 | W30: =SUMIFS('생판재-26FW(ST)'!$BI$4:$BI$5000,'생판재-26FW(ST)'!$H$4:$H$5000,종합!$F30) -> 0 | X30: =SUMIFS('생판재-26FW(ST)'!$BJ$4:$BJ$5000,'생판재-26FW(ST)'!$H$4:$H$5000,종합!$F30) -> 0 | Y30: =IFERROR(1-(W30/V30),"") | Z30: =SUMIFS('생판재-26FW(ST)'!$BC$4:$BC$5000,'생판재-26FW(ST)'!$H$4:$H$5000,종합!$F30) -> 0 | AA30: =SUMIFS('생판재-26FW(ST)'!$BE$4:$BE$5000,'생판재-26FW(ST)'!$H$4:$H$5000,종합!$F30) -> 0 | AD30: OUTER | AE30: CT | AF30: 코트 | AG30: =AG73+AG114 -> 15 | AH30: =AH73+AH114 -> 0 | AI30: =AI73+AI114 -> 18530 | AJ30: =AJ73+AJ114 -> 1 | AK30: =AK73+AK114 -> 0 | AL30: =AL73+AL114 -> 535 | AM30: =IFERROR(AL30/AI30,"") -> 0.028872099 | AN30: =AN73+AN114 -> 1151392800 | AO30: =AO73+AO114 -> 21346500 | AP30: =AO30/AO$109 -> 0.0098270914 | AQ30: =AQ73+AQ114 -> 85065000 | AR30: =AQ30/AQ$109 -> 0.0090818245 | AS30: =IFERROR(AQ30/AO30/1.1,"") -> 3.6226931 | AT30: =AT73+AT114 -> 0 | AU30: =IFERROR(AT30/AL30,"") -> 0 | AV30: =AV73+AV114 -> 0 | AW30: =AW73+AW114 -> 0 | AX30: =AX73+AX114 -> 0 | AY30: =IFERROR(1-(AW30/AV30),"") | AZ30: =AZ73+AZ114 -> 0 | BA30: =BA73+BA114 -> 0 | BE30: OUTER | BF30: CT | BG30: 코트 | BH30: =SUMIFS('주간판매-러닝(CO)'!$P$4:$P$5000,'주간판매-러닝(CO)'!$I$4:$I$5000,종합!$BG30) -> 2 | BI30: =COUNTIFS('주간판매-러닝(CO)'!$I$4:$I$5000,종합!$BG30,'주간판매-러닝(CO)'!$E$4:$E$5000,"가을(러닝)")+ COUNTIFS('주간판매-러닝(CO)'!$I$4:$I$5000,종합!$BG30,'주간판매-러닝(CO)'!$E$4:$E$5000,"겨울(러닝)") -> 8 | BJ30: =SUMIFS('주간판매-러닝(CO)'!$R$4:$R$5000,'주간판매-러닝(CO)'!$I$4:$I$5000,종합!$F30,'주간판매-러닝(CO)'!$E$4:$E$5000,"가을(러닝)")+ SUMIFS('주간판매-러닝(CO)'!$R$4:$R$5000,'주간판매-러닝(CO)'!$I$4:$I$5000,종합!$F30,'주간판매-러닝(CO)'!$E$4:$E$5000,"겨울(러닝)") -> 13700 | BK30: =COUNTIFS('주간판매-러닝(CO)'!$P$4:$P$5000,"A",'주간판매-러닝(CO)'!$I$4:$I$5000,종합!$F30,'주간판매-러닝(CO)'!$V$4:$V$5000,">0",'주간판매-러닝(CO)'!$E$4:$E$5000,"가을(러닝)")+ COUNTIFS('주간판매-러닝(CO)'!$P$4:$P$5000,"A",'주간판매-러닝(CO)'!$I$4:$I$5000,종합!$F30,'주간판매-러닝(CO)'!$V$4:$V$5000,">0",'주간판매-러닝(CO)'!$E$4:$E$5000,"겨울(러닝)") -> 2 | BL30: =COUNTIFS('주간판매-러닝(CO)'!$I$4:$I$5000,종합!$F30,'주간판매-러닝(CO)'!$V$4:$V$5000,">0",'주간판매-러닝(CO)'!$E$4:$E$5000,"가을(러닝)")+ COUNTIFS('주간판매-러닝(CO)'!$I$4:$I$5000,종합!$F30,'주간판매-러닝(CO)'!$V$4:$V$5000,">0",'주간판매-러닝(CO)'!$E$4:$E$5000,"겨울(러닝)") -> 8 | BM30: =SUMIFS('주간판매-러닝(CO)'!$V$4:$V$5000,'주간판매-러닝(CO)'!$I$4:$I$5000,종합!$F30,'주간판매-러닝(CO)'!$E$4:$E$5000,"가을(러닝)")+ SUMIFS('주간판매-러닝(CO)'!$V$4:$V$5000,'주간판매-러닝(CO)'!$I$4:$I$5000,종합!$F30,'주간판매-러닝(CO)'!$E$4:$E$5000,"겨울(러닝)") -> 13859 | BN30: =IFERROR(BM30/BJ30,"") -> 1.0116058 | BO30: =SUMIFS('생판재-러닝(ST)'!$AI$4:$AI$5000,'생판재-러닝(ST)'!$H$4:$H$5000,종합!$F30,'생판재-러닝(ST)'!$D$4:$D$5000,"가을(러닝)")+ SUMIFS('생판재-러닝(ST)'!$AI$4:$AI$5000,'생판재-러닝(ST)'!$H$4:$H$5000,종합!$F30,'생판재-러닝(ST)'!$D$4:$D$5000,"겨울(러닝)") -> 635100000 | BP30: =SUMIFS('생판재-러닝(ST)'!$AR$4:$AR$5000,'생판재-러닝(ST)'!$H$4:$H$5000,종합!$F30,'생판재-러닝(ST)'!$D$4:$D$5000,"가을(러닝)")+ SUMIFS('생판재-러닝(ST)'!$AR$4:$AR$5000,'생판재-러닝(ST)'!$H$4:$H$5000,종합!$F30,'생판재-러닝(ST)'!$D$4:$D$5000,"겨울(러닝)") -> 642248500 | BQ30: =BP30/BP$66 -> 0.20964706 | BR30: =SUMIFS('생판재-러닝(ST)'!$AQ$4:$AQ$5000,'생판재-러닝(ST)'!$H$4:$H$5000,종합!$F30,'생판재-러닝(ST)'!$D$4:$D$5000,"가을(러닝)")+ SUMIFS('생판재-러닝(ST)'!$AQ$4:$AQ$5000,'생판재-러닝(ST)'!$H$4:$H$5000,종합!$F30,'생판재-러닝(ST)'!$D$4:$D$5000,"겨울(러닝)") -> 2899874000 | BS30: =BR30/BR$66 -> 0.2133111 | BT30: =IFERROR(BR30/BP30/1.1,"") -> 4.1047182 | BU30: =SUMIFS('생판재-러닝(ST)'!$BG$4:$BG$5000,'생판재-러닝(ST)'!$H$4:$H$5000,종합!$F30,'생판재-러닝(ST)'!$D$4:$D$5000,"가을(러닝)")+ SUMIFS('생판재-러닝(ST)'!$BG$4:$BG$5000,'생판재-러닝(ST)'!$H$4:$H$5000,종합!$F30,'생판재-러닝(ST)'!$D$4:$D$5000,"겨울(러닝)") -> 29 | BV30: =IFERROR(BU30/BM30,"") -> 0.0020925031 | BW30: =SUMIFS('생판재-러닝(ST)'!$BH$4:$BH$5000,'생판재-러닝(ST)'!$H$4:$H$5000,종합!$F30,'생판재-러닝(ST)'!$D$4:$D$5000,"가을(러닝)")+ SUMIFS('생판재-러닝(ST)'!$BH$4:$BH$5000,'생판재-러닝(ST)'!$H$4:$H$5000,종합!$F30,'생판재-러닝(ST)'!$D$4:$D$5000,"겨울(러닝)") -> 4524000 | BX30: =SUMIFS('생판재-러닝(ST)'!$BI$4:$BI$5000,'생판재-러닝(ST)'!$H$4:$H$5000,종합!$F30,'생판재-러닝(ST)'!$D$4:$D$5000,"가을(러닝)")+ SUMIFS('생판재-러닝(ST)'!$BI$4:$BI$5000,'생판재-러닝(ST)'!$H$4:$H$5000,종합!$F30,'생판재-러닝(ST)'!$D$4:$D$5000,"겨울(러닝)") -> 3521360 | BY30: =SUMIFS('생판재-러닝(ST)'!$BJ$4:$BJ$5000,'생판재-러닝(ST)'!$H$4:$H$5000,종합!$F30,'생판재-러닝(ST)'!$D$4:$D$5000,"가을(러닝)")+ SUMIFS('생판재-러닝(ST)'!$BJ$4:$BJ$5000,'생판재-러닝(ST)'!$H$4:$H$5000,종합!$F30,'생판재-러닝(ST)'!$D$4:$D$5000,"겨울(러닝)") -> 1283250 | BZ30: =IFERROR(1-(BX30/BW30),"") -> 0.22162688 | CA30: =SUMIFS('생판재-러닝(ST)'!$BC$4:$BC$5000,'생판재-러닝(ST)'!$H$4:$H$5000,종합!$F30,'생판재-러닝(ST)'!$D$4:$D$5000,"가을(러닝)")+ SUMIFS('생판재-러닝(ST)'!$BC$4:$BC$5000,'생판재-러닝(ST)'!$H$4:$H$5000,종합!$F30,'생판재-러닝(ST)'!$D$4:$D$5000,"겨울(러닝)") -> 29 | CB30: =SUMIFS('생판재-러닝(ST)'!$BE$4:$BE$5000,'생판재-러닝(ST)'!$H$4:$H$5000,종합!$F30,'생판재-러닝(ST)'!$D$4:$D$5000,"가을(러닝)")+ SUMIFS('생판재-러닝(ST)'!$BE$4:$BE$5000,'생판재-러닝(ST)'!$H$4:$H$5000,종합!$F30,'생판재-러닝(ST)'!$D$4:$D$5000,"겨울(러닝)") -> 3521360 | CE30: OUTER | CF30: CT | CG30: 코트 | CH30: =COUNTIFS('시점재고(~26.07.31, 생판재)'!$H$4:$H$5000,종합!$CG30) -> 2 | CJ30: =SUMIFS('시점재고(~26.07.31, 생판재)'!$BM$4:$BM$5000,'시점재고(~26.07.31, 생판재)'!$H$4:$H$5000,종합!$CG30) -> 2657 | CK30: =SUMIFS('생판재-러닝(ST)'!$BG$4:$BG$5000,'생판재-러닝(ST)'!$H$4:$H$5000,종합!$CG30,'생판재-러닝(ST)'!$D$4:$D$5000,"<>가을(러닝)",'생판재-러닝(ST)'!$D$4:$D$5000,"<>겨울(러닝)")-( SUMIFS('시점재고(~26.07.31, 생판재)'!$BG$4:$BG$5000,'시점재고(~26.07.31, 생판재)'!$H$4:$H$5000,종합!CG30)) -> 156 | CL30: =IFERROR(CK30/#REF!,"") | CM30: =SUMIFS('생판재-러닝(ST)'!$BH$4:$BH$5000,'생판재-러닝(ST)'!$H$4:$H$5000,종합!$F30,'생판재-러닝(ST)'!$D$4:$D$5000,"<>가을(러닝)",'생판재-러닝(ST)'!$D$4:$D$5000,"<>겨울(러닝)")-( SUMIFS('시점재고(~26.07.31, 생판재)'!$BH$4:$BH$5000,'시점재고(~26.07.31, 생판재)'!$H$4:$H$5000,종합!$F30)) -> 24476000 | CN30: =SUMIFS('생판재-러닝(ST)'!$BI$4:$BI$5000,'생판재-러닝(ST)'!$H$4:$H$5000,종합!$F30,'생판재-러닝(ST)'!$D$4:$D$5000,"<>가을(러닝)",'생판재-러닝(ST)'!$D$4:$D$5000,"<>겨울(러닝)")-( SUMIFS('시점재고(~26.07.31, 생판재)'!$BI$4:$BI$5000,'시점재고(~26.07.31, 생판재)'!$H$4:$H$5000,종합!$F30)) -> 18673150 | CO30: =SUMIFS('생판재-러닝(ST)'!$BJ$4:$BJ$5000,'생판재-러닝(ST)'!$H$4:$H$5000,종합!$F30,'생판재-러닝(ST)'!$D$4:$D$5000,"<>가을(러닝)",'생판재-러닝(ST)'!$D$4:$D$5000,"<>겨울(러닝)")-( SUMIFS('시점재고(~26.07.31, 생판재)'!$BJ$4:$BJ$5000,'시점재고(~26.07.31, 생판재)'!$H$4:$H$5000,종합!$F30)) -> 6422000 | CP30: =IFERROR(1-(CN30/CM30),"") -> 0.23708327 | CQ30: =SUMIFS('생판재-러닝(ST)'!$BC$4:$BC$5000,'생판재-러닝(ST)'!$H$4:$H$5000,종합!$F30,'생판재-러닝(ST)'!$D$4:$D$5000,"<>가을(러닝)",'생판재-러닝(ST)'!$D$4:$D$5000,"<>겨울(러닝)") -> 59 | CR30: =SUMIFS('생판재-러닝(ST)'!$BE$4:$BE$5000,'생판재-러닝(ST)'!$H$4:$H$5000,종합!$F30,'생판재-러닝(ST)'!$D$4:$D$5000,"<>가을(러닝)",'생판재-러닝(ST)'!$D$4:$D$5000,"<>겨울(러닝)") -> 7438430
D31: OUTER | E31: JK | F31: 자켓 | G31: =SUMIF('주간판매-26FW(CO)'!$I:$I,종합!$F31,'주간판매-26FW(CO)'!$P:$P) -> 9 | H31: =COUNTIF('주간판매-26FW(CO)'!$I:$I,종합!$F31) -> 21 | I31: =SUMIFS('주간판매-26FW(CO)'!$R$4:$R$5000,'주간판매-26FW(CO)'!$I$4:$I$5000,종합!$F31) -> 11350 | J31: =SUMIFS('주간판매-26FW(CO)'!$P$4:$P$5000,'주간판매-26FW(CO)'!$I$4:$I$5000,종합!$F31,'주간판매-26FW(CO)'!$V$4:$V$5000,">0") -> 5 | K31: =COUNTIFS('주간판매-26FW(CO)'!$I$4:$I$5000,종합!$F31,'주간판매-26FW(CO)'!$V$4:$V$5000,">0") -> 11 | L31: =SUMIFS('주간판매-26FW(CO)'!$V$4:$V$5000,'주간판매-26FW(CO)'!$I$4:$I$5000,종합!$F31) -> 5250 | M31: =IFERROR(L31/I31,"") -> 0.46255507 | N31: =SUMIFS('생판재-26FW(ST)'!$AI$4:$AI$5000,'생판재-26FW(ST)'!$H$4:$H$5000,종합!$F31) -> 413670000 | O31: =SUMIFS('생판재-26FW(ST)'!$AR$4:$AR$5000,'생판재-26FW(ST)'!$H$4:$H$5000,종합!$F31) -> 215998700 | P31: =O31/O$66 -> 0.098073757 | Q31: =SUMIFS('생판재-26FW(ST)'!$AQ$4:$AQ$5000,'생판재-26FW(ST)'!$H$4:$H$5000,종합!$F31) -> 898219000 | R31: =Q31/Q$66 -> 0.097170307 | S31: =IFERROR(Q31/O31/1.1,"") -> 3.7804057 | T31: =SUMIFS('생판재-26FW(ST)'!$BG$4:$BG$5000,'생판재-26FW(ST)'!$H$4:$H$5000,종합!$F31) -> 139 | U31: =IFERROR(T31/L31,"") -> 0.02647619 | V31: =SUMIFS('생판재-26FW(ST)'!$BH$4:$BH$5000,'생판재-26FW(ST)'!$H$4:$H$5000,종합!$F31) -> 18279000 | W31: =SUMIFS('생판재-26FW(ST)'!$BI$4:$BI$5000,'생판재-26FW(ST)'!$H$4:$H$5000,종합!$F31) -> 13688640 | X31: =SUMIFS('생판재-26FW(ST)'!$BJ$4:$BJ$5000,'생판재-26FW(ST)'!$H$4:$H$5000,종합!$F31) -> 4683400 | Y31: =IFERROR(1-(W31/V31),"") -> 0.25112752 | Z31: =SUMIFS('생판재-26FW(ST)'!$BC$4:$BC$5000,'생판재-26FW(ST)'!$H$4:$H$5000,종합!$F31) -> 46 | AA31: =SUMIFS('생판재-26FW(ST)'!$BE$4:$BE$5000,'생판재-26FW(ST)'!$H$4:$H$5000,종합!$F31) -> 4897670 | AD31: OUTER | AE31: JK | AF31: 자켓 | AG31: =AG74+AG115 -> 9 | AH31: =AH74+AH115 -> 0 | AI31: =AI74+AI115 -> 9700 | AJ31: =AJ74+AJ115 -> 5 | AK31: =AK74+AK115 -> 2 | AL31: =AL74+AL115 -> 4327 | AM31: =IFERROR(AL31/AI31,"") -> 0.44608247 | AN31: =AN74+AN115 -> 325607000 | AO31: =AO74+AO115 -> 125536400 | AP31: =AO31/AO$109 -> 0.057792035 | AQ31: =AQ74+AQ115 -> 551926000 | AR31: =AQ31/AQ$109 -> 0.05892547 | AS31: =IFERROR(AQ31/AO31/1.1,"") -> 3.996856 | AT31: =AT74+AT115 -> 252 | AU31: =IFERROR(AT31/AL31,"") -> 0.058238965 | AV31: =AV74+AV115 -> 32051000 | AW31: =AW74+AW115 -> 15497633 | AX31: =AX74+AX115 -> 6855800 | AY31: =IFERROR(1-(AW31/AV31),"") -> 0.5164696 | AZ31: =AZ74+AZ115 -> 54 | BA31: =BA74+BA115 -> 3939163 | BE31: OUTER | BF31: JK | BG31: 자켓 | BH31: =SUMIFS('주간판매-러닝(CO)'!$P$4:$P$5000,'주간판매-러닝(CO)'!$I$4:$I$5000,종합!$BG31) -> 3 | BI31: =COUNTIFS('주간판매-러닝(CO)'!$I$4:$I$5000,종합!$BG31,'주간판매-러닝(CO)'!$E$4:$E$5000,"가을(러닝)")+ COUNTIFS('주간판매-러닝(CO)'!$I$4:$I$5000,종합!$BG31,'주간판매-러닝(CO)'!$E$4:$E$5000,"겨울(러닝)") -> 9 | BJ31: =SUMIFS('주간판매-러닝(CO)'!$R$4:$R$5000,'주간판매-러닝(CO)'!$I$4:$I$5000,종합!$F31,'주간판매-러닝(CO)'!$E$4:$E$5000,"가을(러닝)")+ SUMIFS('주간판매-러닝(CO)'!$R$4:$R$5000,'주간판매-러닝(CO)'!$I$4:$I$5000,종합!$F31,'주간판매-러닝(CO)'!$E$4:$E$5000,"겨울(러닝)") -> 7970 | BK31: =COUNTIFS('주간판매-러닝(CO)'!$P$4:$P$5000,"A",'주간판매-러닝(CO)'!$I$4:$I$5000,종합!$F31,'주간판매-러닝(CO)'!$V$4:$V$5000,">0",'주간판매-러닝(CO)'!$E$4:$E$5000,"가을(러닝)")+ COUNTIFS('주간판매-러닝(CO)'!$P$4:$P$5000,"A",'주간판매-러닝(CO)'!$I$4:$I$5000,종합!$F31,'주간판매-러닝(CO)'!$V$4:$V$5000,">0",'주간판매-러닝(CO)'!$E$4:$E$5000,"겨울(러닝)") -> 3 | BL31: =COUNTIFS('주간판매-러닝(CO)'!$I$4:$I$5000,종합!$F31,'주간판매-러닝(CO)'!$V$4:$V$5000,">0",'주간판매-러닝(CO)'!$E$4:$E$5000,"가을(러닝)")+ COUNTIFS('주간판매-러닝(CO)'!$I$4:$I$5000,종합!$F31,'주간판매-러닝(CO)'!$V$4:$V$5000,">0",'주간판매-러닝(CO)'!$E$4:$E$5000,"겨울(러닝)") -> 9 | BM31: =SUMIFS('주간판매-러닝(CO)'!$V$4:$V$5000,'주간판매-러닝(CO)'!$I$4:$I$5000,종합!$F31,'주간판매-러닝(CO)'!$E$4:$E$5000,"가을(러닝)")+ SUMIFS('주간판매-러닝(CO)'!$V$4:$V$5000,'주간판매-러닝(CO)'!$I$4:$I$5000,종합!$F31,'주간판매-러닝(CO)'!$E$4:$E$5000,"겨울(러닝)") -> 8164 | BN31: =IFERROR(BM31/BJ31,"") -> 1.0243413 | BO31: =SUMIFS('생판재-러닝(ST)'!$AI$4:$AI$5000,'생판재-러닝(ST)'!$H$4:$H$5000,종합!$F31,'생판재-러닝(ST)'!$D$4:$D$5000,"가을(러닝)")+ SUMIFS('생판재-러닝(ST)'!$AI$4:$AI$5000,'생판재-러닝(ST)'!$H$4:$H$5000,종합!$F31,'생판재-러닝(ST)'!$D$4:$D$5000,"겨울(러닝)") -> 277298000 | BP31: =SUMIFS('생판재-러닝(ST)'!$AR$4:$AR$5000,'생판재-러닝(ST)'!$H$4:$H$5000,종합!$F31,'생판재-러닝(ST)'!$D$4:$D$5000,"가을(러닝)")+ SUMIFS('생판재-러닝(ST)'!$AR$4:$AR$5000,'생판재-러닝(ST)'!$H$4:$H$5000,종합!$F31,'생판재-러닝(ST)'!$D$4:$D$5000,"겨울(러닝)") -> 283797170 | BQ31: =BP31/BP$66 -> 0.092638975 | BR31: =SUMIFS('생판재-러닝(ST)'!$AQ$4:$AQ$5000,'생판재-러닝(ST)'!$H$4:$H$5000,종합!$F31,'생판재-러닝(ST)'!$D$4:$D$5000,"가을(러닝)")+ SUMIFS('생판재-러닝(ST)'!$AQ$4:$AQ$5000,'생판재-러닝(ST)'!$H$4:$H$5000,종합!$F31,'생판재-러닝(ST)'!$D$4:$D$5000,"겨울(러닝)") -> 1109139000 | BS31: =BR31/BR$66 -> 0.081586877 | BT31: =IFERROR(BR31/BP31/1.1,"") -> 3.5529184 | BU31: =SUMIFS('생판재-러닝(ST)'!$BG$4:$BG$5000,'생판재-러닝(ST)'!$H$4:$H$5000,종합!$F31,'생판재-러닝(ST)'!$D$4:$D$5000,"가을(러닝)")+ SUMIFS('생판재-러닝(ST)'!$BG$4:$BG$5000,'생판재-러닝(ST)'!$H$4:$H$5000,종합!$F31,'생판재-러닝(ST)'!$D$4:$D$5000,"겨울(러닝)") -> 133 | BV31: =IFERROR(BU31/BM31,"") -> 0.016291034 | BW31: =SUMIFS('생판재-러닝(ST)'!$BH$4:$BH$5000,'생판재-러닝(ST)'!$H$4:$H$5000,종합!$F31,'생판재-러닝(ST)'!$D$4:$D$5000,"가을(러닝)")+ SUMIFS('생판재-러닝(ST)'!$BH$4:$BH$5000,'생판재-러닝(ST)'!$H$4:$H$5000,종합!$F31,'생판재-러닝(ST)'!$D$4:$D$5000,"겨울(러닝)") -> 18133000 | BX31: =SUMIFS('생판재-러닝(ST)'!$BI$4:$BI$5000,'생판재-러닝(ST)'!$H$4:$H$5000,종합!$F31,'생판재-러닝(ST)'!$D$4:$D$5000,"가을(러닝)")+ SUMIFS('생판재-러닝(ST)'!$BI$4:$BI$5000,'생판재-러닝(ST)'!$H$4:$H$5000,종합!$F31,'생판재-러닝(ST)'!$D$4:$D$5000,"겨울(러닝)") -> 13553040 | BY31: =SUMIFS('생판재-러닝(ST)'!$BJ$4:$BJ$5000,'생판재-러닝(ST)'!$H$4:$H$5000,종합!$F31,'생판재-러닝(ST)'!$D$4:$D$5000,"가을(러닝)")+ SUMIFS('생판재-러닝(ST)'!$BJ$4:$BJ$5000,'생판재-러닝(ST)'!$H$4:$H$5000,종합!$F31,'생판재-러닝(ST)'!$D$4:$D$5000,"겨울(러닝)") -> 4635000 | BZ31: =IFERROR(1-(BX31/BW31),"") -> 0.25257597 | CA31: =SUMIFS('생판재-러닝(ST)'!$BC$4:$BC$5000,'생판재-러닝(ST)'!$H$4:$H$5000,종합!$F31,'생판재-러닝(ST)'!$D$4:$D$5000,"가을(러닝)")+ SUMIFS('생판재-러닝(ST)'!$BC$4:$BC$5000,'생판재-러닝(ST)'!$H$4:$H$5000,종합!$F31,'생판재-러닝(ST)'!$D$4:$D$5000,"겨울(러닝)") -> 80 | CB31: =SUMIFS('생판재-러닝(ST)'!$BE$4:$BE$5000,'생판재-러닝(ST)'!$H$4:$H$5000,종합!$F31,'생판재-러닝(ST)'!$D$4:$D$5000,"가을(러닝)")+ SUMIFS('생판재-러닝(ST)'!$BE$4:$BE$5000,'생판재-러닝(ST)'!$H$4:$H$5000,종합!$F31,'생판재-러닝(ST)'!$D$4:$D$5000,"겨울(러닝)") -> 7938380 | CE31: OUTER | CF31: JK | CG31: 자켓 | CH31: =COUNTIFS('시점재고(~26.07.31, 생판재)'!$H$4:$H$5000,종합!$CG31) -> 3 | CJ31: =SUMIFS('시점재고(~26.07.31, 생판재)'!$BM$4:$BM$5000,'시점재고(~26.07.31, 생판재)'!$H$4:$H$5000,종합!$CG31) -> 1185 | CK31: =SUMIFS('생판재-러닝(ST)'!$BG$4:$BG$5000,'생판재-러닝(ST)'!$H$4:$H$5000,종합!$CG31,'생판재-러닝(ST)'!$D$4:$D$5000,"<>가을(러닝)",'생판재-러닝(ST)'!$D$4:$D$5000,"<>겨울(러닝)")-( SUMIFS('시점재고(~26.07.31, 생판재)'!$BG$4:$BG$5000,'시점재고(~26.07.31, 생판재)'!$H$4:$H$5000,종합!CG31)) -> 88 | CL31: =IFERROR(CK31/#REF!,"") | CM31: =SUMIFS('생판재-러닝(ST)'!$BH$4:$BH$5000,'생판재-러닝(ST)'!$H$4:$H$5000,종합!$F31,'생판재-러닝(ST)'!$D$4:$D$5000,"<>가을(러닝)",'생판재-러닝(ST)'!$D$4:$D$5000,"<>겨울(러닝)")-( SUMIFS('시점재고(~26.07.31, 생판재)'!$BH$4:$BH$5000,'시점재고(~26.07.31, 생판재)'!$H$4:$H$5000,종합!$F31)) -> 12330000 | CN31: =SUMIFS('생판재-러닝(ST)'!$BI$4:$BI$5000,'생판재-러닝(ST)'!$H$4:$H$5000,종합!$F31,'생판재-러닝(ST)'!$D$4:$D$5000,"<>가을(러닝)",'생판재-러닝(ST)'!$D$4:$D$5000,"<>겨울(러닝)")-( SUMIFS('시점재고(~26.07.31, 생판재)'!$BI$4:$BI$5000,'시점재고(~26.07.31, 생판재)'!$H$4:$H$5000,종합!$F31)) -> 8885891 | CO31: =SUMIFS('생판재-러닝(ST)'!$BJ$4:$BJ$5000,'생판재-러닝(ST)'!$H$4:$H$5000,종합!$F31,'생판재-러닝(ST)'!$D$4:$D$5000,"<>가을(러닝)",'생판재-러닝(ST)'!$D$4:$D$5000,"<>겨울(러닝)")-( SUMIFS('시점재고(~26.07.31, 생판재)'!$BJ$4:$BJ$5000,'시점재고(~26.07.31, 생판재)'!$H$4:$H$5000,종합!$F31)) -> 3092700 | CP31: =IFERROR(1-(CN31/CM31),"") -> 0.27932758 | CQ31: =SUMIFS('생판재-러닝(ST)'!$BC$4:$BC$5000,'생판재-러닝(ST)'!$H$4:$H$5000,종합!$F31,'생판재-러닝(ST)'!$D$4:$D$5000,"<>가을(러닝)",'생판재-러닝(ST)'!$D$4:$D$5000,"<>겨울(러닝)") -> 44 | CR31: =SUMIFS('생판재-러닝(ST)'!$BE$4:$BE$5000,'생판재-러닝(ST)'!$H$4:$H$5000,종합!$F31,'생판재-러닝(ST)'!$D$4:$D$5000,"<>가을(러닝)",'생판재-러닝(ST)'!$D$4:$D$5000,"<>겨울(러닝)") -> 4761440
D32: OUTER | E32: JP | F32: 점퍼 | G32: =SUMIF('주간판매-26FW(CO)'!$I:$I,종합!$F32,'주간판매-26FW(CO)'!$P:$P) -> 24 | H32: =COUNTIF('주간판매-26FW(CO)'!$I:$I,종합!$F32) -> 48 | I32: =SUMIFS('주간판매-26FW(CO)'!$R$4:$R$5000,'주간판매-26FW(CO)'!$I$4:$I$5000,종합!$F32) -> 27280 | J32: =SUMIFS('주간판매-26FW(CO)'!$P$4:$P$5000,'주간판매-26FW(CO)'!$I$4:$I$5000,종합!$F32,'주간판매-26FW(CO)'!$V$4:$V$5000,">0") -> 8 | K32: =COUNTIFS('주간판매-26FW(CO)'!$I$4:$I$5000,종합!$F32,'주간판매-26FW(CO)'!$V$4:$V$5000,">0") -> 17 | L32: =SUMIFS('주간판매-26FW(CO)'!$V$4:$V$5000,'주간판매-26FW(CO)'!$I$4:$I$5000,종합!$F32) -> 10665 | M32: =IFERROR(L32/I32,"") -> 0.39094575 | N32: =SUMIFS('생판재-26FW(ST)'!$AI$4:$AI$5000,'생판재-26FW(ST)'!$H$4:$H$5000,종합!$F32) -> 804236600 | O32: =SUMIFS('생판재-26FW(ST)'!$AR$4:$AR$5000,'생판재-26FW(ST)'!$H$4:$H$5000,종합!$F32) -> 387168860 | P32: =O32/O$66 -> 0.17579321 | Q32: =SUMIFS('생판재-26FW(ST)'!$AQ$4:$AQ$5000,'생판재-26FW(ST)'!$H$4:$H$5000,종합!$F32) -> 1624529000 | R32: =Q32/Q$66 -> 0.17574331 | S32: =IFERROR(Q32/O32/1.1,"") -> 3.8144714 | T32: =SUMIFS('생판재-26FW(ST)'!$BG$4:$BG$5000,'생판재-26FW(ST)'!$H$4:$H$5000,종합!$F32) -> 96 | U32: =IFERROR(T32/L32,"") -> 0.0090014065 | V32: =SUMIFS('생판재-26FW(ST)'!$BH$4:$BH$5000,'생판재-26FW(ST)'!$H$4:$H$5000,종합!$F32) -> 12310000 | W32: =SUMIFS('생판재-26FW(ST)'!$BI$4:$BI$5000,'생판재-26FW(ST)'!$H$4:$H$5000,종합!$F32) -> 9111840 | X32: =SUMIFS('생판재-26FW(ST)'!$BJ$4:$BJ$5000,'생판재-26FW(ST)'!$H$4:$H$5000,종합!$F32) -> 3291400 | Y32: =IFERROR(1-(W32/V32),"") -> 0.25980179 | Z32: =SUMIFS('생판재-26FW(ST)'!$BC$4:$BC$5000,'생판재-26FW(ST)'!$H$4:$H$5000,종합!$F32) -> 54 | AA32: =SUMIFS('생판재-26FW(ST)'!$BE$4:$BE$5000,'생판재-26FW(ST)'!$H$4:$H$5000,종합!$F32) -> 5356750 | AD32: OUTER | AE32: JP | AF32: 점퍼 | AG32: =AG75+AG116 -> 21 | AH32: =AH75+AH116 -> 0 | AI32: =AI75+AI116 -> 32796 | AJ32: =AJ75+AJ116 -> 2 | AK32: =AK75+AK116 -> 0 | AL32: =AL75+AL116 -> 1677 | AM32: =IFERROR(AL32/AI32,"") -> 0.051134285 | AN32: =AN75+AN116 -> 1164958200 | AO32: =AO75+AO116 -> 45162000 | AP32: =AO32/AO$109 -> 0.020790814 | AQ32: =AQ75+AQ116 -> 209442000 | AR32: =AQ32/AQ$109 -> 0.02236073 | AS32: =IFERROR(AQ32/AO32/1.1,"") -> 4.215974 | AT32: =AT75+AT116 -> 77 | AU32: =IFERROR(AT32/AL32,"") -> 0.045915325 | AV32: =AV75+AV116 -> 9805000 | AW32: =AW75+AW116 -> 5001435 | AX32: =AX75+AX116 -> 2112300 | AY32: =IFERROR(1-(AW32/AV32),"") -> 0.48990974 | AZ32: =AZ75+AZ116 -> 50 | BA32: =BA75+BA116 -> 3960668 | BE32: OUTER | BF32: JP | BG32: 점퍼 | BH32: =SUMIFS('주간판매-러닝(CO)'!$P$4:$P$5000,'주간판매-러닝(CO)'!$I$4:$I$5000,종합!$BG32) -> 3 | BI32: =COUNTIFS('주간판매-러닝(CO)'!$I$4:$I$5000,종합!$BG32,'주간판매-러닝(CO)'!$E$4:$E$5000,"가을(러닝)")+ COUNTIFS('주간판매-러닝(CO)'!$I$4:$I$5000,종합!$BG32,'주간판매-러닝(CO)'!$E$4:$E$5000,"겨울(러닝)") -> 9 | BJ32: =SUMIFS('주간판매-러닝(CO)'!$R$4:$R$5000,'주간판매-러닝(CO)'!$I$4:$I$5000,종합!$F32,'주간판매-러닝(CO)'!$E$4:$E$5000,"가을(러닝)")+ SUMIFS('주간판매-러닝(CO)'!$R$4:$R$5000,'주간판매-러닝(CO)'!$I$4:$I$5000,종합!$F32,'주간판매-러닝(CO)'!$E$4:$E$5000,"겨울(러닝)") -> 7100 | BK32: =COUNTIFS('주간판매-러닝(CO)'!$P$4:$P$5000,"A",'주간판매-러닝(CO)'!$I$4:$I$5000,종합!$F32,'주간판매-러닝(CO)'!$V$4:$V$5000,">0",'주간판매-러닝(CO)'!$E$4:$E$5000,"가을(러닝)")+ COUNTIFS('주간판매-러닝(CO)'!$P$4:$P$5000,"A",'주간판매-러닝(CO)'!$I$4:$I$5000,종합!$F32,'주간판매-러닝(CO)'!$V$4:$V$5000,">0",'주간판매-러닝(CO)'!$E$4:$E$5000,"겨울(러닝)") -> 2 | BL32: =COUNTIFS('주간판매-러닝(CO)'!$I$4:$I$5000,종합!$F32,'주간판매-러닝(CO)'!$V$4:$V$5000,">0",'주간판매-러닝(CO)'!$E$4:$E$5000,"가을(러닝)")+ COUNTIFS('주간판매-러닝(CO)'!$I$4:$I$5000,종합!$F32,'주간판매-러닝(CO)'!$V$4:$V$5000,">0",'주간판매-러닝(CO)'!$E$4:$E$5000,"겨울(러닝)") -> 5 | BM32: =SUMIFS('주간판매-러닝(CO)'!$V$4:$V$5000,'주간판매-러닝(CO)'!$I$4:$I$5000,종합!$F32,'주간판매-러닝(CO)'!$E$4:$E$5000,"가을(러닝)")+ SUMIFS('주간판매-러닝(CO)'!$V$4:$V$5000,'주간판매-러닝(CO)'!$I$4:$I$5000,종합!$F32,'주간판매-러닝(CO)'!$E$4:$E$5000,"겨울(러닝)") -> 3721 | BN32: =IFERROR(BM32/BJ32,"") -> 0.52408451 | BO32: =SUMIFS('생판재-러닝(ST)'!$AI$4:$AI$5000,'생판재-러닝(ST)'!$H$4:$H$5000,종합!$F32,'생판재-러닝(ST)'!$D$4:$D$5000,"가을(러닝)")+ SUMIFS('생판재-러닝(ST)'!$AI$4:$AI$5000,'생판재-러닝(ST)'!$H$4:$H$5000,종합!$F32,'생판재-러닝(ST)'!$D$4:$D$5000,"겨울(러닝)") -> 307210000 | BP32: =SUMIFS('생판재-러닝(ST)'!$AR$4:$AR$5000,'생판재-러닝(ST)'!$H$4:$H$5000,종합!$F32,'생판재-러닝(ST)'!$D$4:$D$5000,"가을(러닝)")+ SUMIFS('생판재-러닝(ST)'!$AR$4:$AR$5000,'생판재-러닝(ST)'!$H$4:$H$5000,종합!$F32,'생판재-러닝(ST)'!$D$4:$D$5000,"겨울(러닝)") -> 161078000 | BQ32: =BP32/BP$66 -> 0.052580161 | BR32: =SUMIFS('생판재-러닝(ST)'!$AQ$4:$AQ$5000,'생판재-러닝(ST)'!$H$4:$H$5000,종합!$F32,'생판재-러닝(ST)'!$D$4:$D$5000,"가을(러닝)")+ SUMIFS('생판재-러닝(ST)'!$AQ$4:$AQ$5000,'생판재-러닝(ST)'!$H$4:$H$5000,종합!$F32,'생판재-러닝(ST)'!$D$4:$D$5000,"겨울(러닝)") -> 686070000 | BS32: =BR32/BR$66 -> 0.050466451 | BT32: =IFERROR(BR32/BP32/1.1,"") -> 3.8720371 | BU32: =SUMIFS('생판재-러닝(ST)'!$BG$4:$BG$5000,'생판재-러닝(ST)'!$H$4:$H$5000,종합!$F32,'생판재-러닝(ST)'!$D$4:$D$5000,"가을(러닝)")+ SUMIFS('생판재-러닝(ST)'!$BG$4:$BG$5000,'생판재-러닝(ST)'!$H$4:$H$5000,종합!$F32,'생판재-러닝(ST)'!$D$4:$D$5000,"겨울(러닝)") -> 14 | BV32: =IFERROR(BU32/BM32,"") -> 0.0037624295 | BW32: =SUMIFS('생판재-러닝(ST)'!$BH$4:$BH$5000,'생판재-러닝(ST)'!$H$4:$H$5000,종합!$F32,'생판재-러닝(ST)'!$D$4:$D$5000,"가을(러닝)")+ SUMIFS('생판재-러닝(ST)'!$BH$4:$BH$5000,'생판재-러닝(ST)'!$H$4:$H$5000,종합!$F32,'생판재-러닝(ST)'!$D$4:$D$5000,"겨울(러닝)") -> 2646000 | BX32: =SUMIFS('생판재-러닝(ST)'!$BI$4:$BI$5000,'생판재-러닝(ST)'!$H$4:$H$5000,종합!$F32,'생판재-러닝(ST)'!$D$4:$D$5000,"가을(러닝)")+ SUMIFS('생판재-러닝(ST)'!$BI$4:$BI$5000,'생판재-러닝(ST)'!$H$4:$H$5000,종합!$F32,'생판재-러닝(ST)'!$D$4:$D$5000,"겨울(러닝)") -> 1822400 | BY32: =SUMIFS('생판재-러닝(ST)'!$BJ$4:$BJ$5000,'생판재-러닝(ST)'!$H$4:$H$5000,종합!$F32,'생판재-러닝(ST)'!$D$4:$D$5000,"가을(러닝)")+ SUMIFS('생판재-러닝(ST)'!$BJ$4:$BJ$5000,'생판재-러닝(ST)'!$H$4:$H$5000,종합!$F32,'생판재-러닝(ST)'!$D$4:$D$5000,"겨울(러닝)") -> 616000 | BZ32: =IFERROR(1-(BX32/BW32),"") -> 0.31126228 | CA32: =SUMIFS('생판재-러닝(ST)'!$BC$4:$BC$5000,'생판재-러닝(ST)'!$H$4:$H$5000,종합!$F32,'생판재-러닝(ST)'!$D$4:$D$5000,"가을(러닝)")+ SUMIFS('생판재-러닝(ST)'!$BC$4:$BC$5000,'생판재-러닝(ST)'!$H$4:$H$5000,종합!$F32,'생판재-러닝(ST)'!$D$4:$D$5000,"겨울(러닝)") -> 14 | CB32: =SUMIFS('생판재-러닝(ST)'!$BE$4:$BE$5000,'생판재-러닝(ST)'!$H$4:$H$5000,종합!$F32,'생판재-러닝(ST)'!$D$4:$D$5000,"가을(러닝)")+ SUMIFS('생판재-러닝(ST)'!$BE$4:$BE$5000,'생판재-러닝(ST)'!$H$4:$H$5000,종합!$F32,'생판재-러닝(ST)'!$D$4:$D$5000,"겨울(러닝)") -> 1822400 | CE32: OUTER | CF32: JP | CG32: 점퍼 | CH32: =COUNTIFS('시점재고(~26.07.31, 생판재)'!$H$4:$H$5000,종합!$CG32) -> 3 | CJ32: =SUMIFS('시점재고(~26.07.31, 생판재)'!$BM$4:$BM$5000,'시점재고(~26.07.31, 생판재)'!$H$4:$H$5000,종합!$CG32) -> 458 | CK32: =SUMIFS('생판재-러닝(ST)'!$BG$4:$BG$5000,'생판재-러닝(ST)'!$H$4:$H$5000,종합!$CG32,'생판재-러닝(ST)'!$D$4:$D$5000,"<>가을(러닝)",'생판재-러닝(ST)'!$D$4:$D$5000,"<>겨울(러닝)")-( SUMIFS('시점재고(~26.07.31, 생판재)'!$BG$4:$BG$5000,'시점재고(~26.07.31, 생판재)'!$H$4:$H$5000,종합!CG32)) -> 25 | CL32: =IFERROR(CK32/#REF!,"") | CM32: =SUMIFS('생판재-러닝(ST)'!$BH$4:$BH$5000,'생판재-러닝(ST)'!$H$4:$H$5000,종합!$F32,'생판재-러닝(ST)'!$D$4:$D$5000,"<>가을(러닝)",'생판재-러닝(ST)'!$D$4:$D$5000,"<>겨울(러닝)")-( SUMIFS('시점재고(~26.07.31, 생판재)'!$BH$4:$BH$5000,'시점재고(~26.07.31, 생판재)'!$H$4:$H$5000,종합!$F32)) -> 3925000 | CN32: =SUMIFS('생판재-러닝(ST)'!$BI$4:$BI$5000,'생판재-러닝(ST)'!$H$4:$H$5000,종합!$F32,'생판재-러닝(ST)'!$D$4:$D$5000,"<>가을(러닝)",'생판재-러닝(ST)'!$D$4:$D$5000,"<>겨울(러닝)")-( SUMIFS('시점재고(~26.07.31, 생판재)'!$BI$4:$BI$5000,'시점재고(~26.07.31, 생판재)'!$H$4:$H$5000,종합!$F32)) -> 2757460 | CO32: =SUMIFS('생판재-러닝(ST)'!$BJ$4:$BJ$5000,'생판재-러닝(ST)'!$H$4:$H$5000,종합!$F32,'생판재-러닝(ST)'!$D$4:$D$5000,"<>가을(러닝)",'생판재-러닝(ST)'!$D$4:$D$5000,"<>겨울(러닝)")-( SUMIFS('시점재고(~26.07.31, 생판재)'!$BJ$4:$BJ$5000,'시점재고(~26.07.31, 생판재)'!$H$4:$H$5000,종합!$F32)) -> 945000 | CP32: =IFERROR(1-(CN32/CM32),"") -> 0.29746242 | CQ32: =SUMIFS('생판재-러닝(ST)'!$BC$4:$BC$5000,'생판재-러닝(ST)'!$H$4:$H$5000,종합!$F32,'생판재-러닝(ST)'!$D$4:$D$5000,"<>가을(러닝)",'생판재-러닝(ST)'!$D$4:$D$5000,"<>겨울(러닝)") -> 2 | CR32: =SUMIFS('생판재-러닝(ST)'!$BE$4:$BE$5000,'생판재-러닝(ST)'!$H$4:$H$5000,종합!$F32,'생판재-러닝(ST)'!$D$4:$D$5000,"<>가을(러닝)",'생판재-러닝(ST)'!$D$4:$D$5000,"<>겨울(러닝)") -> 274760
